Workbook

Sheet In
A1: PHIẾU YẾU CẦU XUẤT KHO NGUYÊN VẬT LIỆU | R1: Mã số: PXK NVL
R2: Ngày ban hành: 8/1/2022
R3: Số phiếu:
A5: Tên khách hàng | C5: =V5 -> CÔNG TY 4 ORANGES CO.,LTD | I5: Thông tin | K5: ĐVT | M5: Thông số | P5: Bộ phận yêu cầu | S5: Bộ phận kho | V5: CÔNG TY 4 ORANGES CO.,LTD | W5: XD1KH00565BP0011 | X5: 4O BTA140 SPEC CEO PUTTY FOR INTERIOR 40KG | Y5: 26BA2HKH00565000014
A6: Tên sản phẩm | C6: =X5 -> 4O BTA140 SPEC CEO PUTTY FOR INTERIOR 40KG | I6: Số lượng đặt | K6: bao | M6: 3000 | P6: Lập | R6: Duyệt | S6: Thủ kho | T6: Duyệt
A7: Mã sản phẩm | C7: =W5 -> XD1KH00565BP0011 | I7: Chiều dài bao sx | K7: mét | M7: 0.82
A8: Số YCSX | C8: =Y5 -> 26BA2HKH00565000014 | I8: Chiều ngang + hông | K8: mét | M8: 0.5
A9: Số phiếu SX | C9: SX2607080 | I9: Số lượng in thực tế | K9: mét | M9: =M6*M7*1.05+400 -> 2983 | P9: Nguyễn Minh Quân | R9: Nguyễn Minh Quân
I10: Số màu in | K10: màu | M10: 3
I11: Khổ mành | K11: mét | M11: =M8*2+0.06 -> 1.06
I12: Khổ màng | K12: mét | M12: =M8*2+0.04 -> 1.04
I13: Khổ giấy | K13: mét
I14: Khối lượng túi lồng | K14: kg | M14: =51/1000 -> 0.051
A16: Tổ sử dụng | B16: STT | C16: Tên NVL | D16: Mã NVL | E16: Số lô/ số lot | F16: Đơn vị | G16: Số lượng yêu cầu | H16: Số lượng thực tế xuất | M16: Ngày xuất | Q16: Trả lại | R16: Số lượng sử dụng | S16: Người xuất | T16: Người nhận
H17: Lần 1 | I17: Lần 2 | J17: Lần 3 | K17: Lần 4 | L17: Tổng | M17: Lần 1 | N17: Lần 2 | O17: Lần 3 | P17: Lần 4
A18: Tổ in | B18: 1 | C18: Màng BOPP mờ K1040 18 mic | D18: MB01810400001 | F18: Kg | G18: =(M9)*M12*0.88*18/1000 -> 49.140749 | S18: Lần 1: Lần 2: Lần 3: Lần 4: | T18: Lần 1: Lần 2: Lần 3: Lần 4: | V18: Mực in OPP LW62 White (Trắng) Ariang | W18: MOCLW62T00001
F19: Mét | G19: =M9 -> 2983 | V19: Mực in OPP 79 Green (Xanh lá) Ariang | W19: MOC79XL000001
B20: 2 | C20: Dung môi OPP | D20: PDMTOLUENE001 | F20: Kg | G20: =0.006*M9*0.7 -> 12.5286 | V20: Mực in OPP LY11-23 Yellow (Vàng chanh) Arirang | W20: MODALY11V0002
B21: 3 | C21: Dung môi EA | D21: PDMEA00001 | F21: Kg | G21: =0.006*M9*0.3 -> 5.3694 | V21: Mực in OPP 94 Black (Đen) Ariang | W21: MOC94D0000001
B22: 4 | C22: Xanh 39 | D22: MODLB39XD0001 | F22: Kg | G22: 14 | V22: Mực in OPP Medium Arirang | W22: MOCLME2100001
B23: 5 | C23: Vàng 23 | D23: MODALY11V0002 | F23: Kg | G23: 6 | V23: Mực in OPP 39 Blue Arirang | W23: MODLB39XD0001
B24: 6 | C24: Đỏ 11 | D24: MOD11DC000001 | F24: Kg | G24: 22
B25: 7 | V25: Mực in OPP 16 Red (Đỏ đậm) Arirang | W25: MOD16DS000002
B26: 8 | V26: Mực in OPP 7549 (Vàng) Arirang (Bestmix) | W26: MOC7549V00001
B27: 9 | C27: Mực in OPP Medium Arirang | D27: MOCLME2100001 | F27: Kg | V27: Mực in OPP 83-2 (Tím) Violet Arirang | W27: MOC832V000001
B28: 10 | C28: Mực OPP tái chế | D28: MOPPHH0000001 | F28: Kg | V28: Mực in OPP Cam 52 Arirang | W28: MOC52C000001
A29: Thành phẩm dự kiến: | F29: Cái | G29: =M6 -> 3000 | V29: Mực in OPP Vàng 2454 (Bestmix) | W29: MOS2454Y00001
A30: GHI CHÚ: | V30: Mực in OPP Tím 2111C (Bestmix) | W30: MOC2111CT0001
A38: Thông tin | B38: ĐVT | C38: Thông số
A39: Số lượng đặt | B39: bao | C39: =M6 -> 3000
A40: Chiều dài bao sx | B40: mét | C40: =M7 -> 0.82 | H40: `
A41: Chiều ngang + hông | B41: mét | C41: =M8 -> 0.5
A42: Số lượng in thực tế | B42: mét | C42: =M9 -> 2983
A43: Số màu in | B43: màu | C43: =M10 -> 3
A44: Khổ mành | B44: mét | C44: =M11 -> 1.06
A45: Khổ màng | B45: mét | C45: =M12 -> 1.04
A46: Khổ giấy | B46: mét | C46: =M13 -> 0
A47: Khối lượng túi lồng | B47: kg | C47: =M14 -> 0.051

Sheet Tráng
A1: PHIẾU YẾU CẦU XUẤT KHO NGUYÊN VẬT LIỆU | R1: Mã số: PXK NVL
R2: Ngày ban hành: 8/1/2022
R3: Số phiếu:
A5: Tên khách hàng | C5: =In!C5:G5 -> CÔNG TY 4 ORANGES CO.,LTD | I5: Thông tin | K5: ĐVT | M5: Thông số | P5: Bộ phận yêu cầu | S5: Bộ phận kho | V5: CÔNG TY TNHH SẢN XUẤT THƯƠNG MẠI DỊCH VỤ VỮNG TIẾN | W5: XD2KH00309BP0002 | X5: Bao đựng keo dán gạch VISION xám 25kg | Y5: 23S03MKH00309000031
A6: Tên sản phẩm | C6: =In!C6:G6 -> 4O BTA140 SPEC CEO PUTTY FOR INTERIOR 40KG | I6: Số lượng đặt | K6: bao | M6: =In!M6 -> 3000 | P6: Lập | R6: Duyệt | S6: Thủ kho | T6: Duyệt
A7: Mã sản phẩm | C7: =In!C7:G7 -> XD1KH00565BP0011 | I7: Chiều dài bao | K7: mét | M7: =In!M7:N7 -> 0.82
A8: Số YCSX | C8: =In!C8:G8 -> 26BA2HKH00565000014 | I8: Chiều ngang + hông | K8: mét | M8: =In!M8:N8 -> 0.5
A9: Số phiếu SX | C9: =In!C9 -> SX2607080 | I9: =In!I9:J9 -> Số lượng in thực tế | K9: mét | M9: =M6*M7*1.05+17 -> 2600 | P9: Nguyễn Minh Quân | R9: Nguyễn Minh Quân
I10: Khổ mành | K10: mét | M10: 1.07
I11: Khổ màng | K11: mét | M11: =M10-0.03 -> 1.04
I12: Khổ giấy | K12: mét
I13: Khối lượng túi lồng | K13: kg | M13: =In!M14:N14 -> 0.051
A15: Tổ sử dụng | B15: STT | C15: Tên NVL | D15: Mã NVL | E15: Số lô/ số lot | F15: Đơn vị | G15: Số lượng yêu cầu | H15: Số lượng thực tế xuất | M15: Ngày xuất | Q15: Trả lại | R15: Số lượng sử dụng | S15: Người xuất | T15: Người nhận
H16: Lần 1 | I16: Lần 2 | J16: Lần 3 | K16: Lần 4 | L16: Tổng | M16: Lần 1 | N16: Lần 2 | O16: Lần 3 | P16: Lần 4
A17: Tổ tráng | B17: 1 | C17: Mành trắng K1060 ĐL75 | D17: MW07510600001 | F17: Kg | G17: =M9*M10*0.075 -> 208.65 | S17: Lần 1: Lần 2: Lần 3: Lần 4: | T17: Lần 1: Lần 2: Lần 3: Lần 4:
B18: 2 | C18: F801C | D18: NHPPNSF801C001 | F18: Kg | G18: =M9*M10*0.02*0.85 -> 47.294
B19: 3 | C19: Taical | D19: NHTEFPP010511 | F19: Kg | G19: =M9*M10*0.02*0.07 -> 3.8948
B20: 4 | C20: Hạt màu | D20: NHMMWD9015001 | F20: Kg | G20: =M9*M10*0.02*0.08 -> 4.4512
B21: 5
B22: 6
A23: GHI CHÚ:
H33: `

Sheet Dán
A1: PHIẾU YẾU CẦU XUẤT KHO NGUYÊN VẬT LIỆU | R1: Mã số: PXK NVL
R2: Ngày ban hành: 8/1/2022
R3: Số phiếu:
A5: Tên khách hàng | C5: =In!C5:G5 -> CÔNG TY 4 ORANGES CO.,LTD | I5: Thông tin | K5: ĐVT | M5: Thông số | P5: Bộ phận yêu cầu | S5: Bộ phận kho | V5: CÔNG TY TNHH SẢN XUẤT THƯƠNG MẠI DỊCH VỤ VỮNG TIẾN | W5: XD2KH00309BP0002 | X5: Bao đựng keo dán gạch VISION xám 25kg | Y5: 23S03MKH00309000031
A6: Tên sản phẩm | C6: =In!C6:G6 -> 4O BTA140 SPEC CEO PUTTY FOR INTERIOR 40KG | I6: Số lượng đặt | K6: bao | M6: =In!M6 -> 3000 | P6: Lập | R6: Duyệt | S6: Thủ kho | T6: Duyệt
A7: Mã sản phẩm | C7: =In!C7:G7 -> XD1KH00565BP0011 | I7: Chiều dài bao | K7: mét | M7: =In!M7:N7 -> 0.82
A8: Số YCSX | C8: =In!C8:G8 -> 26BA2HKH00565000014 | I8: Chiều ngang + hông | K8: mét | M8: =In!M8:N8 -> 0.5
A9: Số phiếu SX | C9: =In!C9 -> SX2607080 | I9: =In!I9:J9 -> Số lượng in thực tế | K9: mét | M9: =Tráng!M9 -> 2600 | P9: Nguyễn Minh Quân | R9: Nguyễn Minh Quân
I10: Khổ mành | K10: mét | M10: =M8*2+0.06 -> 1.06
I11: Khổ màng | K11: mét | M11: =M10-0.02 -> 1.04
I12: Khổ giấy | K12: mét
I13: Khối lượng túi lồng | K13: kg | M13: =In!M14:N14 -> 0.051
A15: Tổ sử dụng | B15: STT | C15: Tên NVL | D15: Mã NVL | E15: Số lô/ số lot | F15: Đơn vị | G15: Số lượng yêu cầu | H15: Số lượng thực tế xuất | M15: Ngày xuất | Q15: Trả lại | R15: Số lượng sử dụng | S15: Người xuất | T15: Người nhận
H16: Lần 1 | I16: Lần 2 | J16: Lần 3 | K16: Lần 4 | L16: Tổng | M16: Lần 1 | N16: Lần 2 | O16: Lần 3 | P16: Lần 4
A17: Dán | B17: 1 | C17: F801C | D17: NHPPNSF801C001 | F17: Kg | G17: =M9*0.5*3.114/1000 -> 4.0482 | S17: Lần 1: Lần 2: Lần 3: | T17: Lần 1: Lần 2: Lần 3:
B18: 2 | C18: Vistamaxx | D18: NHVITAMAX0001 | F18: Kg | G18: =M9*0.5*3.114/1000 -> 4.0482
B19: 3 | C19: Keo Acrylic | D19: PKACRYLIC0001 | F19: Kg | G19: 0
A20: GHI CHÚ:
C22: M9600 | D22: NHPPNSM960001
H30: `

Sheet Thổi
A1: PHIẾU YẾU CẦU XUẤT KHO NGUYÊN VẬT LIỆU | R1: Mã số: PXK NVL
R2: Ngày ban hành: 8/1/2022
R3: Số phiếu:
A5: Tên khách hàng | C5: =In!C5:G5 -> CÔNG TY 4 ORANGES CO.,LTD | I5: Thông tin | K5: ĐVT | M5: Thông số | P5: Bộ phận yêu cầu | S5: Bộ phận kho | V5: CÔNG TY TNHH SẢN XUẤT THƯƠNG MẠI DỊCH VỤ VỮNG TIẾN | W5: XD2KH00309BP0002 | X5: Bao đựng keo dán gạch VISION xám 25kg | Y5: 23S03MKH00309000031
A6: Tên sản phẩm | C6: =In!C6:G6 -> 4O BTA140 SPEC CEO PUTTY FOR INTERIOR 40KG | I6: Số lượng đặt | K6: bao | M6: =In!M6 -> 3000 | P6: Lập | R6: Duyệt | S6: Thủ kho | T6: Duyệt
A7: Mã sản phẩm | C7: =In!C7:G7 -> XD1KH00565BP0011 | I7: Chiều dài bao | K7: mét | M7: =Tráng!M7:N7 -> 0.82
A8: Số YCSX | C8: =In!C8:G8 -> 26BA2HKH00565000014 | I8: Chiều ngang + hông | K8: mét | M8: =Tráng!M8:N8 -> 0.5
A9: Số phiếu SX | C9: =In!C9 -> SX2607080 | I9: =In!I9:J9 -> Số lượng in thực tế | K9: mét | M9: =Tráng!M9:N9 -> 2600 | P9: Nguyễn Minh Quân | R9: Nguyễn Minh Quân
I10: Khổ mành | K10: mét | M10: =Tráng!M10:N10 -> 1.07
I11: Khổ màng | K11: mét | M11: =Tráng!M11:N11 -> 1.04
I12: Khổ giấy | K12: mét
I13: Khối lượng túi lồng | K13: kg | M13: =In!M14:N14 -> 0.051
W14: 893
A15: Tổ sử dụng | B15: STT | C15: Tên NVL | D15: Mã NVL | E15: Số lô/ số lot | F15: Đơn vị | G15: Số lượng yêu cầu | H15: Số lượng thực tế xuất | M15: Ngày xuất | Q15: Trả lại | R15: Số lượng sử dụng | S15: Người xuất | T15: Người nhận | W15: 107
H16: Lần 1 | I16: Lần 2 | J16: Lần 3 | K16: Lần 4 | L16: Tổng | M16: Lần 1 | N16: Lần 2 | O16: Lần 3 | P16: Lần 4
A17: Tổ thổi | B17: 1 | C17: LDPE | D17: NHLLDPEFD21HN | F17: Kg | G17: =M6*M13*0.893*1.05 -> 143.46045 | S17: Lần 1: Lần 2: Lần 3: Lần 4: | T17: Lần 1: Lần 2: Lần 3: Lần 4:
B18: 2 | C18: Hạt taical trắng EFPE 75T | D18: NHTEFPE75T01 | F18: Kg | G18: =M6*M13*0.107*1.05 -> 17.18955
B19: 3 | C19: Túi PE thường 50x100, 50gr, đáy ngắn | D19: TEA050050010002 | F19: Kg | G19: =G17+G18 -> 160.65 | U19: =654-636 -> 18
B20: 4 | F20: Cái | G20: =G19/M13 -> 3150
A21: GHI CHÚ:
D23: NHLLDPEFJF10020SP
H31: `

Sheet May
A1: PHIẾU YẾU CẦU XUẤT KHO NGUYÊN VẬT LIỆU | R1: Mã số: PXK NVL
R2: Ngày ban hành: 8/1/2022
R3: Số phiếu:
A5: Tên khách hàng | C5: =In!C5:G5 -> CÔNG TY 4 ORANGES CO.,LTD | I5: Thông tin | K5: ĐVT | M5: Thông số | P5: Bộ phận yêu cầu | S5: Bộ phận kho | V5: CÔNG TY TNHH SẢN XUẤT THƯƠNG MẠI DỊCH VỤ VỮNG TIẾN | W5: XD2KH00309BP0002 | X5: Bao đựng keo dán gạch VISION xám 25kg | Y5: 23S03MKH00309000031
A6: Tên sản phẩm | C6: =In!C6:G6 -> 4O BTA140 SPEC CEO PUTTY FOR INTERIOR 40KG | I6: Số lượng đặt | K6: bao | M6: =In!M6 -> 3000 | P6: Lập | R6: Duyệt | S6: Thủ kho | T6: Duyệt
A7: Mã sản phẩm | C7: =In!C7:G7 -> XD1KH00565BP0011 | I7: Chiều dài bao | K7: mét | M7: =In!M7:N7 -> 0.82
A8: Số YCSX | C8: =In!C8:G8 -> 26BA2HKH00565000014 | I8: Chiều ngang + hông | K8: mét | M8: =In!M8:N8 -> 0.5
A9: Số phiếu SX | C9: =In!C9 -> SX2607080 | I9: =In!I9:J9 -> Số lượng in thực tế | K9: mét | M9: =Tráng!M9:N9 -> 2600 | P9: Nguyễn Minh Quân | R9: Nguyễn Minh Quân
I10: Khổ mành | K10: mét | M10: =M8*2+0.06 -> 1.06
I11: Khổ màng | K11: mét | M11: =M10-0.02 -> 1.04
I12: Khổ giấy | K12: mét
I13: Khối lượng túi lồng | K13: kg | M13: =In!M14:N14 -> 0.051
A15: Tổ sử dụng | B15: STT | C15: Tên NVL | D15: Mã NVL | E15: Số lô/ số lot | F15: Đơn vị | G15: Số lượng yêu cầu | H15: Số lượng thực tế xuất | M15: Ngày xuất | Q15: Trả lại | R15: Số lượng sử dụng | S15: Người xuất | T15: Người nhận
H16: Lần 1 | I16: Lần 2 | J16: Lần 3 | K16: Lần 4 | L16: Tổng | M16: Lần 1 | N16: Lần 2 | O16: Lần 3 | P16: Lần 4
A17: May | B17: 1 | C17: Chỉ may trắng | D17: VC10000000001 | F17: Kg | G17: =0.8*M6/1000 -> 2.4 | S17: Lần 1: Lần 2: Lần 3: | T17: Lần 1: Lần 2: Lần 3:
B18: 2 | C18: Dây bó bao xám | D18: VC40000000001 | F18: Kg | G18: 1
B19: 3 | C19: =Thổi!C19 -> Túi PE thường 50x100, 50gr, đáy ngắn | D19: =Thổi!D19 -> TEA050050010002 | F19: Kg
F20: Cái | G20: =Thổi!G20 -> 3150
B21: 4
B22: 5
A23: GHI CHÚ:
H33: `

Sheet X
U5: CÔNG TY TNHH SẢN XUẤT THƯƠNG MẠI DỊCH VỤ VỮNG TIẾN | V5: XD2KH00309BP0002 | W5: Bao đựng keo dán gạch VISION xám 25kg | X5: 23S03MKH00309000031
T34: \
A49: KẾ HOẠCH | F49: QUẢN LÝ CHẤT LƯỢNG | M49: NGƯỜI NHẬN
A51: (Ký xác nhận) | F51: (Ký xác nhận) | M51: (Ký xác nhận)
A56: Ngày ........../.........../ 2026 | F56: Ngày ........../.........../ 2026 | M56: Ngày ........../.........../ 2026

Sheet Đóng gói 1
C1: LỆNH SẢN XUẤT | J1: Số hiệu: QTKSX-BM03
J2: Phiên bản: 00
J3: Hiệu lực: 2023-11-09 | N3: =[1]In!J5 -> SX2311007
A5: Số phiếu YCSX: | C5: =In!C8 -> 26BA2HKH00565000014 | I5: Số phiếu: | J5: =In!C9 -> SX2607080 | U5: CÔNG TY TNHH SẢN XUẤT THƯƠNG MẠI DỊCH VỤ VỮNG TIẾN | V5: XD2KH00309BP0002 | W5: Bao đựng keo dán gạch VISION xám 25kg | X5: 23S03MKH00309000031
A6: Mã sản phẩm: | C6: =In!C7 -> XD1KH00565BP0011 | I6: Tổ: | J6: May
A7: Tên sản phẩm: | C7: =In!C6 -> 4O BTA140 SPEC CEO PUTTY FOR INTERIOR 40KG | I7: Ngày bắt đầu: | J7: …..h…..;….../….../2026
A8: Tên khách hàng: | C8: =In!C5 -> CÔNG TY 4 ORANGES CO.,LTD | I8: Ngày kết thúc: | J8: …..h…..;….../….../2026
C10: Người lập phiếu | H10: Người phê duyệt
A11: Họ và tên | C11: Nguyễn Minh Quân | H11: Nguyễn Minh Quân
A12: Chức vụ | C12: Nhân viên kế hoạch | H12: TP Kế hoạch
A13: Chữ ký
A15: Công Đoạn: Đóng gói | I15: Tổ trưởng kiểm tra
A16: Loại bao | C16: ='In 1'!C16 -> Bao OPP | I16: Kết quả | K16: Xác nhận
A17: Kích thước SX | C17: ='In 1'!C17 -> (420 + 80) x 820 | F17: mm
A18: Kích thước TP | C18: ='In 1'!C18 -> (420 + 80) x 790 | F18: mm
A19: Số lượng PO | C19: =In!M6 -> 3000 | F19: bao
A20: Sản lượng yêu cầu | C20: =C19 -> 3000 | F20: bao
A22: Ca vận hành | C22: Ngày | D22: Nhân viên | G22: Số lượng (bao) | I22: Ghi chú
A23: Ca ngày 7h30 - 19h30
A29: Ca vận hành | C29: Ngày | D29: Nhân viên | G29: Số lượng (bao) | I29: Ghi chú
A30: Ca đêm 19h30 - 7h30
A35: Tổng sản lượng
A37: Ghi chú | I37: Bên giao (ký, họ & tên) | K37: Bên nhận (ký, họ & tên)

Sheet May 1
C1: LỆNH SẢN XUẤT | J1: Số hiệu: QTKSX-BM03
J2: Phiên bản: 00 | N2: =[1]In!J5 -> SX2311007
J3: Hiệu lực: 2023-11-09
A5: Số phiếu YCSX: | C5: =In!C8 -> 26BA2HKH00565000014 | I5: Số phiếu: | J5: =In!C9 -> SX2607080 | U5: CÔNG TY TNHH SẢN XUẤT THƯƠNG MẠI DỊCH VỤ VỮNG TIẾN | V5: XD2KH00309BP0002 | W5: Bao đựng keo dán gạch VISION xám 25kg | X5: 23S03MKH00309000031
A6: Mã sản phẩm: | C6: =In!C7 -> XD1KH00565BP0011 | I6: Tổ: | J6: May
A7: Tên sản phẩm: | C7: =In!C6 -> 4O BTA140 SPEC CEO PUTTY FOR INTERIOR 40KG | I7: Ngày bắt đầu: | J7: …..h…..;….../….../2026
A8: Tên khách hàng: | C8: =In!C5 -> CÔNG TY 4 ORANGES CO.,LTD | I8: Ngày kết thúc: | J8: …..h…..;….../….../2026
C10: Người lập phiếu | H10: Người phê duyệt
A11: Họ và tên | C11: Nguyễn Minh Quân | H11: Nguyễn Minh Quân
A12: Chức vụ | C12: Nhân viên kế hoạch | H12: TP Kế hoạch
A13: Chữ ký
A15: Công Đoạn: May, lồng túi | I15: Tổ trưởng kiểm tra
A16: Loại bao | C16: ='In 1'!C16 -> Bao OPP | I16: Kết quả | K16: Xác nhận
A17: Kích thước SX | C17: ='In 1'!C17 -> (420 + 80) x 820 | F17: mm
A18: Kích thước TP | C18: ='In 1'!C18 -> (420 + 80) x 790 | F18: mm
A19: Số lượng PO | C19: =In!M6 -> 3000 | F19: bao
A20: Sản lượng yêu cầu | C20: =C19 -> 3000 | F20: bao
A22: Ca vận hành | C22: Ngày | D22: Nhân viên | G22: Số lượng (bao) | I22: Ghi chú
A23: Ca ngày 7h30 - 19h30
A29: Ca vận hành | C29: Ngày | D29: Nhân viên | G29: Số lượng (bao) | I29: Ghi chú
A30: Ca đêm 19h30 - 7h30
A35: Tổng sản lượng
A37: Ghi chú | I37: Bên giao (ký, họ & tên) | K37: Bên nhận (ký, họ & tên)

Sheet Thổi 1
C1: LỆNH SẢN XUẤT | J1: Số hiệu: QTKSX-BM03
J2: Phiên bản: 00 | N2: =[1]In!J5 -> SX2311007
J3: Hiệu lực: 01/10/2023
A5: Số phiếu YCSX: | C5: =In!C8 -> 26BA2HKH00565000014 | I5: Số phiếu: | J5: =In!C9 -> SX2607080 | U5: CÔNG TY TNHH SẢN XUẤT THƯƠNG MẠI DỊCH VỤ VỮNG TIẾN | V5: XD2KH00309BP0002 | W5: Bao đựng keo dán gạch VISION xám 25kg | X5: 23S03MKH00309000031
A6: Mã sản phẩm: | C6: =In!C7 -> XD1KH00565BP0011 | I6: Tổ: | J6: Thổi
A7: Tên sản phẩm: | C7: =In!C6 -> 4O BTA140 SPEC CEO PUTTY FOR INTERIOR 40KG | I7: Ngày bắt đầu: | J7: …..h…..;….../….../2026
A8: Tên khách hàng: | C8: =In!C5 -> CÔNG TY 4 ORANGES CO.,LTD | I8: Ngày kết thúc: | J8: …..h…..;….../….../2026
C10: Người lập phiếu | H10: Người phê duyệt
A11: Họ và tên | C11: Nguyễn Minh Quân | H11: Nguyễn Minh Quân
A12: Chức vụ | C12: Nhân viên kế hoạch | H12: TP Kế hoạch
A13: Chữ ký
A15: Công Đoạn: Thổi - Cắt | I15: Tổ trưởng kiểm tra
A16: Loại bao | C16: ='In 1'!C16 -> Bao OPP | I16: Kết quả | K16: Xác nhận
A17: Kích thước SX | C17: ='In 1'!C17 -> (420 + 80) x 820 | F17: mm
A18: Kích thước TP | C18: ='In 1'!C18 -> (420 + 80) x 790 | F18: mm
A19: Số lượng PO | C19: =In!M6 -> 3000 | F19: bao
A20: Sản lượng yêu cầu | C20: =Thổi!G19 -> 160.65 | F20: kg
A22: Ca vận hành | C22: Ngày | D22: Nhân viên | G22: Khối lượng (Kg) | I22: Ghi chú
A23: Ca ngày 7h30 - 19h30
A29: Ca vận hành | C29: Ngày | D29: Nhân viên | G29: Khối lượng (Kg) | I29: Ghi chú
A30: Ca đêm 19h30 - 7h30
A35: Tổng sản lượng
A37: Ghi chú | I37: Bên giao (ký, họ & tên) | K37: Bên nhận (ký, họ & tên)

Sheet Dán 1
C1: LỆNH SẢN XUẤT | J1: Số hiệu: QTKSX-BM03
J2: Phiên bản: 00 | N2: =[1]In!J5 -> SX2311007
J3: Hiệu lực: 2023-11-09
A5: Số phiếu YCSX: | C5: =In!C8 -> 26BA2HKH00565000014 | I5: Số phiếu: | J5: =In!C9 -> SX2607080 | U5: CÔNG TY TNHH SẢN XUẤT THƯƠNG MẠI DỊCH VỤ VỮNG TIẾN | V5: XD2KH00309BP0002 | W5: Bao đựng keo dán gạch VISION xám 25kg | X5: 23S03MKH00309000031
A6: Mã sản phẩm: | C6: =In!C7 -> XD1KH00565BP0011 | I6: Tổ: | J6: Tráng - Dán
A7: Tên sản phẩm: | C7: =In!C6 -> 4O BTA140 SPEC CEO PUTTY FOR INTERIOR 40KG | I7: Ngày bắt đầu: | J7: …..h…..;….../….../2026
A8: Tên khách hàng: | C8: =In!C5 -> CÔNG TY 4 ORANGES CO.,LTD | I8: Ngày kết thúc: | J8: …..h…..;….../….../2026
C10: Người lập phiếu | H10: Người phê duyệt
A11: Họ và tên | C11: Nguyễn Minh Quân | H11: Nguyễn Minh Quân
A12: Chức vụ | C12: Nhân viên kế hoạch | H12: TP Kế hoạch
A13: Chữ ký
A15: Công Đoạn: Dán Cắt | I15: Tổ trưởng kiểm tra
A16: Loại bao | C16: ='In 1'!O16 -> Bao OPP | I16: Kết quả | K16: Xác nhận
A17: Kích thước SX | C17: ='In 1'!C17 -> (420 + 80) x 820 | F17: mm
A18: Kích thước TP | C18: ='In 1'!C18 -> (420 + 80) x 790 | F18: mm
A19: Số lượng PO | C19: =In!M6 -> 3000 | F19: bao
A20: Sản lượng yêu cầu | C20: =Tráng!M9 -> 2600 | F20: m
A22: Ca vận hành | C22: Ngày | D22: Nhân viên | G22: Chiều dài (mét) | I22: Ghi chú
A23: Ca ngày 7h30 - 19h30
A29: Ca vận hành | C29: Ngày | D29: Nhân viên | G29: Chiều dài (mét) | I29: Ghi chú
A30: Ca đêm 19h30 - 7h30
A35: Tổng sản lượng
A37: Ghi chú | I37: Bên giao (ký, họ & tên) | K37: Bên nhận (ký, họ & tên)

Sheet Tráng 1
C1: LỆNH SẢN XUẤT | J1: Số hiệu: QTKSX-BM03
J2: Phiên bản: 00 | N2: =[1]In!J5 -> SX2311007
J3: Hiệu lực: 2023-11-09
A5: Số phiếu YCSX: | C5: =In!C8 -> 26BA2HKH00565000014 | I5: Số phiếu: | J5: =In!C9 -> SX2607080 | U5: CÔNG TY TNHH SẢN XUẤT THƯƠNG MẠI DỊCH VỤ VỮNG TIẾN | V5: XD2KH00309BP0002 | W5: Bao đựng keo dán gạch VISION xám 25kg | X5: 23S03MKH00309000031
A6: Mã sản phẩm: | C6: =In!C7 -> XD1KH00565BP0011 | I6: Tổ: | J6: Tráng - Dán
A7: Tên sản phẩm: | C7: =In!C6 -> 4O BTA140 SPEC CEO PUTTY FOR INTERIOR 40KG | I7: Ngày bắt đầu: | J7: …..h…..;….../….../2026
A8: Tên khách hàng: | C8: =In!C5 -> CÔNG TY 4 ORANGES CO.,LTD | I8: Ngày kết thúc: | J8: …..h…..;….../….../2026
C10: Người lập phiếu | H10: Người phê duyệt
A11: Họ và tên | C11: Nguyễn Minh Quân | H11: Nguyễn Minh Quân
A12: Chức vụ | C12: Nhân viên kế hoạch | H12: TP Kế hoạch
A13: Chữ ký
A15: Công Đoạn: Tráng Ghép | I15: Tổ trưởng kiểm tra
A16: Loại bao | C16: ='In 1'!O16 -> Bao OPP | I16: Kết quả | K16: Xác nhận
A17: Kích thước SX | C17: ='In 1'!C17 -> (420 + 80) x 820 | F17: mm
A18: Kích thước TP | C18: ='In 1'!C18 -> (420 + 80) x 790 | F18: mm
A19: Số lượng PO | C19: =In!M6 -> 3000 | F19: bao
A20: Sản lượng yêu cầu | C20: =Tráng!M9 -> 2600 | F20: m
A22: Ca vận hành | C22: Ngày | D22: Nhân viên | G22: Chiều dài (mét) | I22: Ghi chú
A23: Ca ngày 7h30 - 19h30
A29: Ca vận hành | C29: Ngày | D29: Nhân viên | G29: Chiều dài (mét) | I29: Ghi chú
A30: Ca đêm 19h30 - 7h30
A35: Tổng sản lượng
A37: Ghi chú | I37: Bên giao (ký, họ & tên) | K37: Bên nhận (ký, họ & tên)

Sheet Chia biên 1
C1: LỆNH SẢN XUẤT | J1: Số hiệu: QTKSX-BM03
J2: Phiên bản: 00 | N2: =[1]In!J5 -> SX2311007
J3: Hiệu lực: 2023-11-09
A5: Số phiếu YCSX: | C5: =In!C8 -> 26BA2HKH00565000014 | I5: Số phiếu: | J5: =In!C9 -> SX2607080 | U5: CÔNG TY TNHH SẢN XUẤT THƯƠNG MẠI DỊCH VỤ VỮNG TIẾN | V5: XD2KH00309BP0002 | W5: Bao đựng keo dán gạch VISION xám 25kg | X5: 23S03MKH00309000031
A6: Mã sản phẩm: | C6: =In!C7 -> XD1KH00565BP0011 | I6: Tổ: | J6: In
A7: Tên sản phẩm: | C7: =In!C6 -> 4O BTA140 SPEC CEO PUTTY FOR INTERIOR 40KG | I7: Ngày bắt đầu: | J7: …..h…..;….../….../2026
A8: Tên khách hàng: | C8: =In!C5 -> CÔNG TY 4 ORANGES CO.,LTD | I8: Ngày kết thúc: | J8: …..h…..;….../….../2026
C10: Người lập phiếu | H10: Người phê duyệt
A11: Họ và tên | C11: Nguyễn Minh Quân | H11: Nguyễn Minh Quân
A12: Chức vụ | C12: Nhân viên kế hoạch | H12: TP Kế hoạch
A13: Chữ ký
A15: Công Đoạn: Chia cuộn | I15: Tổ trưởng kiểm tra
A16: Loại bao | C16: ='In 1'!O16 -> Bao OPP | I16: Kết quả | K16: Xác nhận
A17: Kích thước SX | C17: ='In 1'!O17 -> (420 + 80) x 820 | F17: mm
A18: Kích thước TP | C18: ='In 1'!O18 -> (420 + 80) x 790 | F18: mm
A19: Số lượng PO | C19: =In!M6 -> 3000 | F19: bao
A20: Sản lượng yêu cầu | C20: =Tráng!M9 -> 2600 | F20: m
A22: Ca vận hành | C22: Ngày | D22: Nhân viên | G22: Chiều dài (mét) | I22: Ghi chú
A23: Ca ngày 7h30 - 19h30
A29: Ca vận hành | C29: Ngày | D29: Nhân viên | G29: Chiều dài (mét) | I29: Ghi chú
A30: Ca đêm 19h30 - 7h30
A35: Tổng sản lượng
A37: Ghi chú | I37: Bên giao (ký, họ & tên) | K37: Bên nhận (ký, họ & tên)

Sheet In 1
C1: LỆNH SẢN XUẤT | J1: Số hiệu: QTKSX-BM03
J2: Phiên bản: 00
J3: Hiệu lực: 2023-11-09
A5: Số phiếu YCSX: | C5: =In!C8 -> 26BA2HKH00565000014 | I5: Số phiếu: | J5: =In!C9 -> SX2607080 | U5: CÔNG TY TNHH SẢN XUẤT THƯƠNG MẠI DỊCH VỤ VỮNG TIẾN | V5: XD2KH00309BP0002 | W5: Bao đựng keo dán gạch VISION xám 25kg | X5: 23S03MKH00309000031
A6: Mã sản phẩm: | C6: =In!C7 -> XD1KH00565BP0011 | I6: Tổ: | J6: In
A7: Tên sản phẩm: | C7: =In!C6 -> 4O BTA140 SPEC CEO PUTTY FOR INTERIOR 40KG | I7: Ngày bắt đầu: | J7: …..h…..;….../….../2026
A8: Tên khách hàng: | C8: =In!C5 -> CÔNG TY 4 ORANGES CO.,LTD | I8: Ngày kết thúc: | J8: …..h…..;….../….../2026
C10: Người lập phiếu | H10: Người phê duyệt
A11: Họ và tên | C11: Nguyễn Minh Quân | H11: Nguyễn Minh Quân
A12: Chức vụ | C12: Nhân viên kế hoạch | H12: TP Kế hoạch
A13: Chữ ký
A15: Công Đoạn: In Ống Đồng | I15: Tổ trưởng kiểm tra
A16: Loại bao | C16: =O16 -> Bao OPP | I16: Kết quả | K16: Xác nhận | N16: Loại bao | O16: Bao OPP
A17: Kích thước SX | C17: =O17 -> (420 + 80) x 820 | F17: mm | N17: Kích thước SX | O17: (420 + 80) x 820
A18: Kích thước TP | C18: =O18 -> (420 + 80) x 790 | F18: mm | N18: Kích thước TP | O18: (420 + 80) x 790
A19: Số lượng PO | C19: =In!M6 -> 3000 | F19: bao | N19: Số lượng PO | O19: 5000
A20: Sản lượng yêu cầu | C20: =In!M9 -> 2983 | F20: m
A22: Ca vận hành | C22: Ngày | D22: Nhân viên | G22: Chiều dài (mét) | I22: Ghi chú
A23: Ca ngày 7h30 - 19h30
A29: Ca vận hành | C29: Ngày | D29: Nhân viên | G29: Chiều dài (mét) | I29: Ghi chú
A30: Ca đêm 19h30 - 7h30
A35: Tổng sản lượng
A37: Ghi chú | I37: Bên giao (ký, họ & tên) | K37: Bên nhận (ký, họ & tên)

Sheet Ghép 1
C1: LỆNH SẢN XUẤT | J1: Số hiệu: QTKSX-BM03
J2: Phiên bản: 00 | N2: =[1]In!J5 -> SX2311007
J3: Hiệu lực: 01/10/2023
A5: Số phiếu YCSX: | C5: =In!C8 -> 26BA2HKH00565000014 | I5: Số phiếu: | J5: =In!C9 -> SX2607080
A6: Mã sản phẩm: | C6: =In!C7 -> XD1KH00565BP0011 | I6: Tổ: | J6: In
A7: Tên sản phẩm: | C7: =In!C6 -> 4O BTA140 SPEC CEO PUTTY FOR INTERIOR 40KG | I7: Ngày bắt đầu: | J7: …..h…..;….../….../2023
A8: Tên khách hàng: | C8: =In!C5 -> CÔNG TY 4 ORANGES CO.,LTD | I8: Ngày kết thúc: | J8: …..h…..;….../….../2023
C10: Người lập phiếu | H10: Người phê duyệt
A11: Họ và tên | C11: Phạm Thành Luân
A12: Chức vụ | C12: Nhân viên kế hoạch
A13: Chữ ký
A15: Công Đoạn: Ghép | I15: Tổ trưởng kiểm tra
A16: Loại bao | C16: =[1]In!O16 -> Bao OPP, may gập đáy 1 đầu bao, MTLS | I16: Kết quả | K16: Xác nhận
A17: Kích thước SX | C17: ='In 1'!O17 -> (420 + 80) x 820 | F17: mm
A18: Kích thước TP | C18: ='In 1'!O18 -> (420 + 80) x 790 | F18: mm
A19: Số lượng PO | C19: =In!M6 -> 3000 | F19: bao
A20: Sản lượng yêu cầu | C20: =In!M9 -> 2983 | F20: m
A22: Ca vận hành | C22: Ngày | D22: Nhân viên | G22: Chiều dài (mét) | I22: Ghi chú
A23: Ca ngày 7h30 - 19h30
A29: Ca vận hành | C29: Ngày | D29: Nhân viên | G29: Chiều dài (mét) | I29: Ghi chú
A30: Ca đêm 19h30 - 7h30
A35: Tổng sản lượng
A37: Ghi chú | I37: Bên giao (ký, họ & tên) | K37: Bên nhận (ký, họ & tên)

Sheet Bồi 1
C1: LỆNH SẢN XUẤT | J1: Số hiệu: QTKSX-BM03
J2: Phiên bản: 00 | N2: =[1]In!J5 -> SX2311007
J3: Hiệu lực: 01/10/2023
A5: Số phiếu YCSX: | C5: =In!C8 -> 26BA2HKH00565000014 | I5: Số phiếu: | J5: =In!C9 -> SX2607080
A6: Mã sản phẩm: | C6: =In!C7 -> XD1KH00565BP0011 | I6: Tổ: | J6: In
A7: Tên sản phẩm: | C7: =In!C6 -> 4O BTA140 SPEC CEO PUTTY FOR INTERIOR 40KG | I7: Ngày bắt đầu: | J7: …..h…..;….../….../2023
A8: Tên khách hàng: | C8: =In!C5 -> CÔNG TY 4 ORANGES CO.,LTD | I8: Ngày kết thúc: | J8: …..h…..;….../….../2023
C10: Người lập phiếu | H10: Người phê duyệt
A11: Họ và tên | C11: Phạm Thành Luân
A12: Chức vụ | C12: Nhân viên kế hoạch
A13: Chữ ký
A15: Công Đoạn: Bồi | I15: Tổ trưởng kiểm tra
A16: Loại bao | C16: =[1]In!O16 -> Bao OPP, may gập đáy 1 đầu bao, MTLS | I16: Kết quả | K16: Xác nhận
A17: Kích thước SX | C17: ='In 1'!C17 -> (420 + 80) x 820 | F17: mm
A18: Kích thước TP | C18: ='In 1'!C18 -> (420 + 80) x 790 | F18: mm
A19: Số lượng PO | C19: =In!M6 -> 3000 | F19: bao
A20: Sản lượng yêu cầu | C20: =In!M9 -> 2983 | F20: m
A22: Ca vận hành | C22: Ngày | D22: Nhân viên | G22: Chiều dài (mét) | I22: Ghi chú
A23: Ca ngày 7h30 - 19h30
A29: Ca vận hành | C29: Ngày | D29: Nhân viên | G29: Chiều dài (mét) | I29: Ghi chú
A30: Ca đêm 19h30 - 7h30
A35: Tổng sản lượng
A37: Ghi chú | I37: Bên giao (ký, họ & tên) | K37: Bên nhận (ký, họ & tên)

Sheet XX

Sheet In 2
C1: NHẬT KÝ SẢN XUẤT | K1: Số hiệu: QTSXU-BM01
K2: Phiên bản: 00
K3: Hiệu lực: 2023-11-09
A5: Số phiếu YCSX: | C5: =In!C8 -> 26BA2HKH00565000014 | I5: Số phiếu: | K5: =In!C9 -> SX2607080 | U5: CÔNG TY TNHH SẢN XUẤT THƯƠNG MẠI DỊCH VỤ VỮNG TIẾN | V5: XD2KH00309BP0002 | W5: Bao đựng keo dán gạch VISION xám 25kg | X5: 23S03MKH00309000031
A6: Mã sản phẩm: | C6: =In!C7 -> XD1KH00565BP0011 | I6: Tổ : | K6: In
A7: Tên sản phẩm: | C7: =In!C6 -> 4O BTA140 SPEC CEO PUTTY FOR INTERIOR 40KG | I7: Ngày bắt đầu: | K7: …..h…..;….../….../2026
A8: Tên khách hàng: | C8: =In!C5 -> CÔNG TY 4 ORANGES CO.,LTD | I8: Ngày kết thúc: | K8: …..h…..;….../….../2026
C10: Người lập phiếu | H10: Người phê duyệt
A11: Họ và tên | C11: Nguyễn Minh Quân | H11: Nguyễn Minh Quân
A12: Chức vụ | C12: Nhân viên kế hoạch | H12: TP Kế hoạch
A13: Chữ ký
A15: Công Đoạn: In Ống Đồng | J15: Nhân viên kiểm tra NVL | O15: Đen 94 | P15: MOC94D0000001
A16: Số lượng theo PO (Mét) | C16: =In!M6*In!M7*1.05 -> 2583 | E16: Số lượng thực tế (Mét) | G16: =In!M9 -> 2983 | J16: Kết quả | L16: Xác nhận | O16: Xanh 39 | P16: MODLB39XD0001
A17: STT | B17: Tên NVL | C17: Mã NVL | D17: Tỷ lệ | E17: ĐVT | F17: Định mức | G17: Thực tế | H17: Trả về | O17: Vàng 23 | P17: MODALY11V0002
B18: =In!C18 -> Màng BOPP mờ K1040 18 mic | C18: =In!D18 -> MB01810400001 | E18: Kg | F18: =In!G18 -> 49.140749 | O18: Đỏ 11 | P18: MOD11DC000001
E19: Mét | F19: =In!G19 -> 2983
B20: =In!C20 -> Dung môi OPP | C20: =In!D20 -> PDMTOLUENE001 | E20: Kg | F20: =In!G20 -> 12.5286
B21: =In!C21 -> Dung môi EA | C21: =In!D21 -> PDMEA00001 | E21: Kg | F21: =In!G21 -> 5.3694
A22: 1 | B22: Đỏ 11 | C22: MOD11DC000001 | E22: Kg | F22: 14 | J22: Kiểm soát chất lượng
J23: Kết quả | L23: Xác nhận
A26: 2 | B26: Xanh 39 | C26: MODLB39XD0001 | E26: Kg | F26: 14
O27: Vàng 23 | P27: MODALY11V0002 | Q27: 0.44 | R27: Kg | S27: 7
J28: Giám sát kỹ thuật | O28: Đỏ 11 | P28: MOD11DC000001 | Q28: 0.06 | R28: Kg | S28: 1
J29: Kết quả | L29: Xác nhận | O29: Đen 94 | P29: MOC94D0000001 | Q29: 0.06 | R29: Kg | S29: 1
A30: 3 | B30: Vàng 23 | C30: MODALY11V0002 | E30: Kg | F30: 6
B31: Đỏ 11 | C31: MOD11DC000001 | E31: Kg | F31: 8
O32: Trắng 62 | P32: MOCLW62T00001 | Q32: 0.31 | R32: Kg | S32: 5
A33: 4 | O33: Medium Arirang | P33: MOCLME2100001 | Q33: 0.13 | R33: Kg | S33: 2
J34: STT | K34: Nhân viên | L34: Chức Vụ | M34: Ký tên
J35: 1 | O35: Vàng 23 | P35: MODALY11V0002 | Q35: 0.33 | R35: Kg | S35: 4
J36: 2 | O36: Đen 94 | P36: MOC94D0000001 | Q36: 0.08 | R36: Kg | S36: 1
A37: 5 | J37: 3
J38: 4 | O38: Đỏ 11 | P38: MOD11DC000001 | Q38: 0.07 | R38: Kg | S38: 1
J39: 5 | O39: Đen 94 | P39: MOC94D0000001 | Q39: 0.33 | R39: Kg | S39: 5
J40: 6 | O40: Trắng 62 | P40: MOCLW62T00001 | Q40: 0.47 | R40: Kg | S40: 7
J41: 4 | O41: Xanh 39 | P41: MODLB39XD0001 | Q41: 0.07 | R41: Kg | S41: 1
J42: 5
J43: 6
A45: STT | B45: Thông số quá trình | D45: Tiêu chuẩn | E45: Kết quả kiểm tra | G45: Đơn vị | H45: Xác nhận | J45: Phế liệu | K45: Khối lượng (Kg) | L45: Người cân | M45: QLCL
E46: ____:____ | F46: ____:____
...

Sheet Chia biên 2
C1: NHẬT KÝ SẢN XUẤT | K1: Số hiệu: QTSXU-BM01
K2: Phiên bản: 00
K3: Hiệu lực: 2023-11-09
A5: Số phiếu YCSX: | C5: ='In 2'!C5 -> 26BA2HKH00565000014 | I5: Số phiếu: | K5: ='In 2'!K5 -> SX2607080 | U5: CÔNG TY TNHH SẢN XUẤT THƯƠNG MẠI DỊCH VỤ VỮNG TIẾN | V5: XD2KH00309BP0002 | W5: Bao đựng keo dán gạch VISION xám 25kg | X5: 23S03MKH00309000031
A6: Mã sản phẩm: | C6: ='In 2'!C6 -> XD1KH00565BP0011 | I6: Tổ : | K6: In
A7: Tên sản phẩm: | C7: ='In 2'!C7 -> 4O BTA140 SPEC CEO PUTTY FOR INTERIOR 40KG | I7: Ngày bắt đầu: | K7: …..h…..;….../….../2026
A8: Tên khách hàng: | C8: ='In 2'!C8 -> CÔNG TY 4 ORANGES CO.,LTD | I8: Ngày kết thúc: | K8: …..h…..;….../….../2026
C10: Người lập phiếu | H10: Người phê duyệt
A11: Họ và tên | C11: Nguyễn Minh Quân | H11: Nguyễn Minh Quân
A12: Chức vụ | C12: Nhân viên kế hoạch | H12: TP Kế hoạch
A13: Chữ ký
A15: Công Đoạn: Chia Cuộn | J15: Nhân viên kiểm tra NVL
A16: Số lượng theo PO (Mét) | C16: =Tráng!M9 -> 2600 | E16: Số lượng thực tế (Mét) | G16: =Tráng!M9 -> 2600 | J16: Kết quả | L16: Xác nhận
A17: STT | B17: Tên NVL | D17: Mã NVL | E17: Tỷ lệ | F17: ĐVT | G17: Định mức | H17: Thực tế
A18: 1
A19: 2
A20: 3 | J20: Kiểm soát chất lượng
A21: 4 | J21: Kết quả | L21: Xác nhận
A22: 5
A23: 6
J24: Giám sát kỹ thuật
J25: Kết quả | L25: Xác nhận
A28: STT | B28: Thông số quá trình | D28: Tiêu chuẩn | E28: Kết quả kiểm tra | G28: Đơn vị | H28: Xác nhận | J28: STT | K28: Nhân viên | L28: Chức Vụ | M28: Ký tên
E29: ____:____ | F29: ____:____ | J29: 1
A30: 1 | B30: Lực thắng cuộn | D30: 4 ± 1 | G30: V | J30: 2
A31: 2 | B31: Lực quấn | D31: 45 ± 10 | G31: RPM | J31: 3
A32: 3 | B32: Tốc độ kéo | D32: 110 ± 10 | G32: Hz | J32: 4
A33: 4 | B33: Khoảng cách từ điểm cắt đến biên cắt | D33: 3 ± 1 | G33: mm | J33: 5
A34: 5
A35: 6 | J35: Phế liệu | K35: Khối lượng (Kg) | L35: Người cân | M35: QLCL
A36: 7
A37: 8
A38: 9
A39: 10
A40: 11
A42: STT | B42: Thông số sản phẩm | D42: Tiêu chuẩn | E42: Kết quả kiểm tra | G42: Đơn vị | H42: Xác nhận
E43: ____:____ | F43: ____:____
A44: 1 | B44: Cuộn xả tối đa | D44: 8000 | G44: m
A45: 2 | B45: Cuộn quấn tối đa | D45: 8000 | G45: m
A46: 3 | B46: Khổ màng chia biên | D46: =O46 -> 1020 | G46: mm | O46: =(In!M12-0.02)*1000 -> 1020
...

Sheet Tráng 2
C1: NHẬT KÝ SẢN XUẤT | N1: Số hiệu: QTSXU-BM01
N2: Phiên bản: 00
N3: Hiệu lực: 2023-11-09
A5: Số phiếu YCSX: | C5: ='In 2'!C5 -> 26BA2HKH00565000014 | M5: Số phiếu: | N5: ='In 2'!K5 -> SX2607080 | U5: CÔNG TY TNHH SẢN XUẤT THƯƠNG MẠI DỊCH VỤ VỮNG TIẾN | V5: XD2KH00309BP0002 | W5: Bao đựng keo dán gạch VISION xám 25kg | X5: 23S03MKH00309000031
A6: Mã sản phẩm: | C6: ='In 2'!C6 -> XD1KH00565BP0011 | M6: Tổ : | N6: Tráng - Dán
A7: Tên sản phẩm: | C7: ='In 2'!C7 -> 4O BTA140 SPEC CEO PUTTY FOR INTERIOR 40KG | M7: Ngày bắt đầu: | N7: …..h…..;….../….../2026
A8: Tên khách hàng: | C8: ='In 2'!C8 -> CÔNG TY 4 ORANGES CO.,LTD | M8: Ngày kết thúc: | N8: …..h…..;….../….../2026
C10: Người lập phiếu | K10: Người phê duyệt
A11: Họ và tên | C11: Nguyễn Minh Quân | K11: Nguyễn Minh Quân
A12: Chức vụ | C12: Nhân viên kế hoạch | K12: TP Kế hoạch
A13: Chữ ký
A15: Công Đoạn: Tráng Ghép | J15: Nhân viên kiểm tra NVL
A16: Thành phẩm chia biên | C16: =Tráng!M9 -> 2600 | F16: Mét | J16: Kết quả | N16: Xác nhận
A17: Mã mành sản xuất
A18: Khối lượng nhựa cần | C18: =G21+G22+G23 -> 55.64 | F18: Kg
A19: STT | B19: Tên NVL | C19: Mã NVL | E19: Tỷ lệ | F19: ĐVT | G19: Định mức | H19: Thực tế
A20: 2 | B20: =Tráng!C17 -> Mành trắng K1060 ĐL75 | C20: =Tráng!D17 -> MW07510600001 | F20: Kg | G20: =Tráng!G17 -> 208.65 | J20: Kiểm soát chất lượng
A21: 3 | B21: =Tráng!C18 -> F801C | C21: =Tráng!D18 -> NHPPNSF801C001 | E21: 0.85 | F21: Kg | G21: =Tráng!G18 -> 47.294 | J21: Kết quả | N21: Xác nhận
A22: 4 | B22: =Tráng!C19 -> Taical | C22: =Tráng!D19 -> NHTEFPP010511 | E22: 0.07 | F22: Kg | G22: =Tráng!G19 -> 3.8948
A23: 5 | B23: =Tráng!C20 -> Hạt màu | C23: =Tráng!D20 -> NHMMWD9015001 | E23: 0.08 | F23: Kg | G23: =Tráng!G20 -> 4.4512
J24: Giám sát kỹ thuật
J25: Kết quả | N25: Xác nhận
A28: STT | B28: Thông số quá trình | D28: Tiêu chuẩn | E28: Kết quả kiểm tra | G28: Đơn vị | H28: Xác nhận | J28: STT | K28: Thông số sản phẩm | M28: Tiêu chuẩn | N28: Kết quả kiểm tra | P28: Đơn vị | Q28: Xác nhận
E29: ____:____ | F29: ____:____ | N29: ____:____ | O29: ____:____
A30: 1 | B30: Tốc độ máy | D30: 97 ± 5 | G30: m/phút | J30: 1 | K30: Độ rộng đường dán | M30: 35 - 40 | P30: mm
A31: 2 | B31: Lực thắng cuộn | D31: 5 - 24 | G31: V | J31: 2 | K31: Khổ thành phẩm | M31: 1040 | P31: mm
A32: 3 | B32: Lực ép lô | D32: 5.5 ± 0.5 | G32: Bar | J32: 3 | K32: Định lượng TP | M32: 115 ± 3 | P32: G/m²
A33: 4 | B33: Nhiệt độ làm mát lô | D33: 24 ± 2 | G33: °C | J33: 4 | K33: Định lượng keo | M33: 20 | P33: G/m²
A34: 5 | B34: Tốc độ quấn cuộn | D34: 65 ± 5 | G34: Hz | J34: 5 | K34: Độ bám dính | M34: Không bong tróc
A35: 6 | B35: Thông số nhiệt đầu khuôn vùng 1 | D35: 290 ± 2 | G35: °C | J35: 6 | K35: Ngoại quan | M35: Không nhăn Không gồ Không cao mép Không đổ cuộn
A36: 7 | B36: Thông số nhiệt đầu khuôn vùng 2 | D36: 290 ± 2 | G36: °C
A37: 8 | B37: Thông số nhiệt đầu khuôn vùng 3 | D37: 290 ± 2 | G37: °C
A38: 9 | B38: Thông số nhiệt đầu khuôn vùng 4 | D38: 290 ± 2 | G38: °C
A39: 10 | B39: Thông số nhiệt đầu khuôn vùng 5 | D39: 290 ± 2 | G39: °C | J39: STT | K39: Nhân viên | N39: Chức vụ | P39: Ký tên
A40: 11 | B40: Thông số nhiệt đầu khuôn vùng 6 | D40: 290 ± 2 | G40: °C | J40: 1
A41: 12 | B41: Thông số nhiệt đầu khuôn vùng 7 | D41: 290 ± 2 | G41: °C | J41: 2
A42: 13 | B42: Thông số nhiệt trục vít vùng 0 | D42: 220 ± 2 | G42: °C | J42: 3
A43: 14 | B43: Thông số nhiệt trục vít vùng 1 | D43: 225 ± 2 | G43: °C | J43: 4
A44: 15 | B44: Thông số nhiệt trục vít vùng 2 | D44: 250 ± 2 | G44: °C | J44: 5
A45: 16 | B45: Thông số nhiệt trục vít vùng 3 | D45: 255 ± 2 | G45: °C
...

Sheet Dán 2
C1: NHẬT KÝ SẢN XUẤT | K1: Số hiệu: QTSXU-BM01
K2: Phiên bản: 00
K3: Hiệu lực: 2023-11-09
A5: Số phiếu YCSX: | C5: ='In 2'!C5 -> 26BA2HKH00565000014 | I5: Số phiếu: | K5: ='In 2'!K5 -> SX2607080 | U5: CÔNG TY TNHH SẢN XUẤT THƯƠNG MẠI DỊCH VỤ VỮNG TIẾN | V5: XD2KH00309BP0002 | W5: Bao đựng keo dán gạch VISION xám 25kg | X5: 23S03MKH00309000031
A6: Mã sản phẩm: | C6: ='In 2'!C6 -> XD1KH00565BP0011 | I6: Tổ : | K6: Tráng - Dán
A7: Tên sản phẩm: | C7: ='In 2'!C7 -> 4O BTA140 SPEC CEO PUTTY FOR INTERIOR 40KG | I7: Ngày bắt đầu: | K7: …..h…..;….../….../2026
A8: Tên khách hàng: | C8: ='In 2'!C8 -> CÔNG TY 4 ORANGES CO.,LTD | I8: Ngày kết thúc: | K8: …..h…..;….../….../2026
C10: Người lập phiếu | H10: Người phê duyệt
A11: Họ và tên | C11: Nguyễn Minh Quân | H11: Nguyễn Minh Quân
A12: Chức vụ | C12: Nhân viên kế hoạch | H12: TP Kế hoạch
A13: Chữ ký
A15: Công Đoạn: Dán Cắt | J15: Nhân viên kiểm tra NVL
A16: Khối lượng nhựa cần | D16: =G18+G19 -> 8.0964 | F16: Kg | J16: Kết quả | L16: Xác nhận
A17: STT | B17: Tên NVL | D17: Mã NVL | E17: Tỷ lệ | F17: ĐVT | G17: Định mức | H17: Thực tế
A18: 1 | B18: =Dán!C17 -> F801C | D18: =Dán!D17 -> NHPPNSF801C001 | E18: 0.5 | F18: Kg | G18: =Dán!G17 -> 4.0482
A19: 2 | B19: =Dán!C18 -> Vistamaxx | D19: =Dán!D18 -> NHVITAMAX0001 | E19: 0.5 | F19: Kg | G19: =Dán!G18 -> 4.0482
A20: 3 | B20: =Dán!C19 -> Keo Acrylic | D20: =Dán!D19 -> PKACRYLIC0001 | J20: Kiểm soát chất lượng
A21: 4 | J21: Kết quả | L21: Xác nhận
A22: 5
A23: 6
J24: Giám sát kỹ thuật
J25: Kết quả | L25: Xác nhận
A28: STT | B28: Thông số quá trình | D28: Tiêu chuẩn | E28: Kết quả kiểm tra | G28: Đơn vị | H28: Xác nhận | J28: STT | K28: Nhân viên | L28: Chức Vụ | M28: Ký tên
E29: ____:____ | F29: ____:____ | J29: 1
A30: 1 | B30: Tốc độ máy | D30: 90 ± 10 | G30: m/phút | J30: 2
A31: 2 | B31: Tốc độ keo | D31: 35 ± 7 | G31: Hz | J31: 3
A32: 3 | B32: Lái cuộn | D32: 560 ± 10 | G32: mm | J32: 4
A33: 4 | B33: Lực ép đường dán | D33: 5 ± 1 | G33: Bar | J33: 5
A34: 5 | B34: Kích thước nhông | D34: 820 | G34: mm
A35: 6 | B35: Số đường keo | D35: 7 | G35: Đường | J35: Phế liệu | K35: Khối lượng (Kg) | L35: Người cân | M35: QLCL
A36: 7 | B36: Điều chỉnh dưỡng | D36: 190 ± 10 | G36: mm
A37: 8 | B37: Độ sâu tối đa của dĩa xếp hong | D37: 40 ± 3 | G37: mm
A38: 9 | B38: Nhiệt độ đầu khuôn | D38: 270 ± 5 | G38: °C
A39: 10 | B39: Nhiệt độ trục vít vùng 1 | D39: 255 ± 5 | G39: °C
A40: 11 | B40: Nhiệt độ trục vít vùng 2 | D40: 280 ± 5 | G40: °C
A41: 12 | B41: Nhiệt độ trục vít vùng 3 | D41: 280 ± 5 | G41: °C
A43: STT | B43: Thông số sản phẩm | D43: Tiêu chuẩn | E43: Kết quả kiểm tra | G43: Đơn vị | H43: Xác nhận
E44: ____:____ | F44: ____:____
A45: 1 | B45: Kích thước chiều dài | D45: 820 ± 5 | G45: mm
A46: 2 | B46: Kích thước chiều rộng | D46: 420 ± 5 | G46: mm
...

Sheet Thổi 2
C1: NHẬT KÝ SẢN XUẤT | K1: Số hiệu: QTSXU-BM01
K2: Phiên bản: 00
K3: Hiệu lực: 01/10/2023
A5: Số phiếu YCSX: | C5: ='In 2'!C5 -> 26BA2HKH00565000014 | I5: Số phiếu: | K5: ='In 2'!K5 -> SX2607080 | U5: CÔNG TY TNHH SẢN XUẤT THƯƠNG MẠI DỊCH VỤ VỮNG TIẾN | V5: XD2KH00309BP0002 | W5: Bao đựng keo dán gạch VISION xám 25kg | X5: 23S03MKH00309000031
A6: Mã sản phẩm: | C6: ='In 2'!C6 -> XD1KH00565BP0011 | I6: Tổ : | K6: Thổi
A7: Tên sản phẩm: | C7: ='In 2'!C7 -> 4O BTA140 SPEC CEO PUTTY FOR INTERIOR 40KG | I7: Ngày bắt đầu: | K7: …..h…..;….../….../2026
A8: Tên khách hàng: | C8: ='In 2'!C8 -> CÔNG TY 4 ORANGES CO.,LTD | I8: Ngày kết thúc: | K8: …..h…..;….../….../2026
C10: Người lập phiếu | H10: Người phê duyệt
A11: Họ và tên | C11: Nguyễn Minh Quân | H11: Nguyễn Minh Quân
A12: Chức vụ | C12: Nhân viên kế hoạch | H12: TP Kế hoạch
A13: Chữ ký
A15: Công Đoạn: Thổi - Cắt | J15: Nhân viên kiểm tra NVL
A16: Khối lượng nhựa cần | D16: =G18+G19 -> 160.65 | F16: Kg | J16: Kết quả | L16: Xác nhận
A17: STT | B17: Tên NVL | D17: Mã NVL | E17: Tỷ lệ | F17: ĐVT | G17: Định mức | H17: Thực tế
A18: 1 | B18: =Thổi!C17 -> LDPE | D18: =Thổi!D17 -> NHLLDPEFD21HN | E18: 0.893 | F18: Kg | G18: =Thổi!G17 -> 143.46045
A19: 2 | B19: =Thổi!C18 -> Hạt taical trắng EFPE 75T | D19: =Thổi!D18 -> NHTEFPE75T01 | E19: 0.107 | F19: Kg | G19: =Thổi!G18 -> 17.18955
A20: 3 | B20: =Thổi!C19 -> Túi PE thường 50x100, 50gr, đáy ngắn | D20: =Thổi!D19 -> TEA050050010002 | F20: Kg | G20: =Thổi!G19 -> 160.65 | J20: Kiểm soát chất lượng
A21: 4 | F21: Cái | G21: =Thổi!G20 -> 3150 | J21: Kết quả | L21: Xác nhận
A22: 5
A23: 6
J24: Giám sát kỹ thuật
J25: Kết quả | L25: Xác nhận
A28: STT | B28: Thông số quá trình | D28: Tiêu chuẩn | E28: Kết quả kiểm tra | G28: Đơn vị | H28: Xác nhận | J28: STT | K28: Nhân viên | L28: Chức Vụ | M28: Ký tên
E29: ____:____ | F29: ____:____ | J29: 1
A30: 1 | B30: Lực quấn cuộn | D30: Trọng lượng BTP từ 0 đến 15kg: 180 ± 10 Trọng lượng BTP từ 16 đến 35kg: 195 ± 10 Trọng lượng BTP từ 36 đến 50kg: 220 ± 10 | G30: RPM | J30: 2
J31: 3
J32: 4
J33: 5
A34: 2 | B34: Thông số nhiệt vùng 1 | D34: 130 | G34: °C
A35: 3 | B35: Thông số nhiệt vùng 2 | D35: 140 | G35: °C | J35: Phế liệu | K35: Khối lượng (Kg) | L35: Người cân | M35: QLCL
A36: 4 | B36: Thông số nhiệt vùng 3 | D36: 150 | G36: °C
A37: 5 | B37: Thông số nhiệt vùng 4 | D37: 170 | G37: °C
A38: 6 | B38: Thông số nhiệt vùng 5 | D38: 170 | G38: °C | O38: =50*100*2*0.93 -> 9300
A39: 7 | B39: Tốc độ đùn keo | D39: 55 ± 5 | G39: Hz | O39: =50*10000/O38 -> 53.763441
A40: 8 | B40: Tốc độ kéo bóng | D40: 35 ± 5 | G40: Hz
A43: STT | B43: Thông số quá trình | D43: Tiêu chuẩn | E43: Kết quả kiểm tra | G43: Đơn vị | H43: Xác nhận
E44: ____:____ | F44: ____:____
A45: 1 | B45: Kích thước chiều rộng | D45: 500 ± 10 | G45: mm
A46: 2 | B46: Kích thước chiều dài | D46: 1000 ± 10 | G46: mm
A47: 3 | B47: Kích thước đáy | D47: 20 - 30 | G47: mm
...

Sheet May 2
C1: NHẬT KÝ SẢN XUẤT | K1: Số hiệu: QTSXU-BM01
K2: Phiên bản: 00
K3: Hiệu lực: 2023-11-09
A5: Số phiếu YCSX: | C5: ='In 2'!C5 -> 26BA2HKH00565000014 | I5: Số phiếu: | K5: ='In 2'!K5 -> SX2607080 | U5: CÔNG TY TNHH SẢN XUẤT THƯƠNG MẠI DỊCH VỤ VỮNG TIẾN | V5: XD2KH00309BP0002 | W5: Bao đựng keo dán gạch VISION xám 25kg | X5: 23S03MKH00309000031
A6: Mã sản phẩm: | C6: ='In 2'!C6 -> XD1KH00565BP0011 | I6: Tổ : | K6: May
A7: Tên sản phẩm: | C7: ='In 2'!C7 -> 4O BTA140 SPEC CEO PUTTY FOR INTERIOR 40KG | I7: Ngày bắt đầu: | K7: …..h…..;….../….../2026
A8: Tên khách hàng: | C8: ='In 2'!C8 -> CÔNG TY 4 ORANGES CO.,LTD | I8: Ngày kết thúc: | K8: …..h…..;….../….../2026
C10: Người lập phiếu | H10: Người phê duyệt
A11: Họ và tên | C11: Nguyễn Minh Quân | H11: Nguyễn Minh Quân
A12: Chức vụ | C12: Nhân viên kế hoạch | H12: TP Kế hoạch
A13: Chữ ký
A15: Công Đoạn: May - Lồng túi | J15: Nhân viên kiểm tra NVL
A16: Số lượng theo PO | C16: =In!M6 -> 3000 | F16: Bao | J16: Kết quả | L16: Xác nhận
A17: STT | B17: Tên NVL | C17: Mã NVL | E17: ĐVT | F17: Tạm ứng | G17: Định mức | H17: Trả về
A18: 1 | B18: =May!C17 -> Chỉ may trắng | C18: =May!D17 -> VC10000000001 | E18: Kg | F18: =May!G17 -> 2.4
A19: 2 | B19: =May!C19 -> Túi PE thường 50x100, 50gr, đáy ngắn | C19: =May!D19 -> TEA050050010002 | E19: Kg | F19: =May!G19 -> 0
A20: 3 | E20: Cái | F20: =May!G20 -> 3150 | J20: Kiểm soát chất lượng
A21: 4 | G21: =May!G21 -> 0 | J21: Kết quả | L21: Xác nhận
A22: 5
A23: 6
J24: Giám sát kỹ thuật
J25: Kết quả | L25: Xác nhận
A28: STT | B28: Thông số | C28: Tiêu chuẩn | E28: Kết quả kiểm tra | G28: Đơn vị | H28: Xác nhận | J28: STT | K28: Nhân viên | L28: Chức Vụ | M28: Ký tên
E29: ____:____ | F29: ____:____ | J29: 1
A30: 1 | B30: May | C30: Không bỏ mũi Không đứt chỉ, rối chỉ Không dính dầu nhớt | J30: 2
J31: 3 | P31: Không tưa chỉ Không xổ chỉ
J32: 4 | P32: Không xổ chỉ
A33: 2 | B33: Cắt chỉ | C33: Không tưa chỉ Không xổ chỉ | J33: 5
A35: 3 | B35: Lồng túi | C35: Đúng yêu cầu Không rách túi Không lòi túi | J35: Phế liệu | K35: Khối lượng (Kg) | L35: Người cân | M35: QLCL | P35: Chênh lệch 2 đầu bao ≤20mm
A37: 4 | B37: Quy cách | C37: MTLS
J48: Ghi chú
A56: Thành phẩm may | J56: Bên giao (ký, họ & tên) | L56: Bên nhận (ký, họ & tên)
A57: Khối lượng (Kg) | E57: Số lượng (Bao)

Sheet Đóng gói 2
C1: NHẬT KÝ SẢN XUẤT | K1: Số hiệu: QTSXU-BM01
K2: Phiên bản: 00
K3: Hiệu lực: 2023-11-09
A5: Số phiếu YCSX: | C5: ='In 2'!C5 -> 26BA2HKH00565000014 | I5: Số phiếu: | K5: ='In 2'!K5 -> SX2607080 | U5: CÔNG TY TNHH SẢN XUẤT THƯƠNG MẠI DỊCH VỤ VỮNG TIẾN | V5: XD2KH00309BP0002 | W5: Bao đựng keo dán gạch VISION xám 25kg | X5: 23S03MKH00309000031
A6: Mã sản phẩm: | C6: ='In 2'!C6 -> XD1KH00565BP0011 | I6: Tổ : | K6: May
A7: Tên sản phẩm: | C7: ='In 2'!C7 -> 4O BTA140 SPEC CEO PUTTY FOR INTERIOR 40KG | I7: Ngày bắt đầu: | K7: …..h…..;….../….../2026
A8: Tên khách hàng: | C8: ='In 2'!C8 -> CÔNG TY 4 ORANGES CO.,LTD | I8: Ngày kết thúc: | K8: …..h…..;….../….../2026
C10: Người lập phiếu | H10: Người phê duyệt
A11: Họ và tên | C11: Nguyễn Minh Quân | H11: Nguyễn Minh Quân
A12: Chức vụ | C12: Nhân viên kế hoạch | H12: TP Kế hoạch
A13: Chữ ký
A15: Công Đoạn: Đóng Gói | J15: Nhân viên kiểm tra NVL
A16: Số lượng theo PO | C16: =In!M6 -> 3000 | F16: Bao | J16: Kết quả | L16: Xác nhận
A17: STT | B17: Tên NVL | C17: Mã NVL | E17: Tỷ lệ | F17: ĐVT | G17: Định mức | H17: Thực tế
A18: 1 | B18: =May!C18 -> Dây bó bao xám | C18: =May!D18 -> VC40000000001 | F18: Kg | G18: =May!G18 -> 1
A19: 2
A20: 3 | J20: Kiểm soát chất lượng
A21: 4 | J21: Kết quả | L21: Xác nhận
A22: 5
A23: 6
A25: STT | B25: Thông số | C25: Tiêu chuẩn | E25: Kết quả kiểm tra | G25: Đơn vị | H25: Xác nhận | J25: STT | K25: Nhân viên | L25: Chức Vụ | M25: Ký tên
E26: ____:____ | F26: ____:____ | J26: 1
A27: 1 | B27: Bó bao | C27: 100 bao/bó Lật mặt trước bao lên trên | J27: 2
J28: 3
A29: 2 | B29: Đóng gói | C29: Đúng yêu cầu số bao/kiện Buộc dây chắc, không xộc xệch Đúng màu sắc dây theo yêu cầu Không có dị vật rơi vào | J29: 4
J30: 5
A32: 3 | B32: Quy cách | C32: 200 bao/kiện | J32: Phế liệu | K32: Khối lượng (Kg) | L32: Người cân | M32: QLCL
J43: Ghi chú
A50: Thành phẩm | J50: Bên giao (ký, họ & tên) | L50: Bên nhận (ký, họ & tên)
A51: Khối lượng (Kg) | D51: Số lượng (Bó) | F51: Số lượng (Bao)
