Workbook

Sheet In
A1: PHIẾU YẾU CẦU XUẤT KHO NGUYÊN VẬT LIỆU | R1: Mã số: PXK NVL
R2: Ngày ban hành: 8/1/2022
R3: Số phiếu:
A5: Tên khách hàng | I5: Thông tin | K5: ĐVT | M5: Thông số | P5: Bộ phận yêu cầu | S5: Bộ phận kho | V5: NHÀ MÁY SX TINH BỘT SẮN TÂN CHÂU-CN CÔNG TY CPNS THỰC PHẨM QUẢNG NGÃI | W5: BT1KH00563KP0004 | X5: Bao giấy 25kg AM-20 Tân Châu | Y5: 26BA2HKH00563000029
A6: Tên sản phẩm | I6: Số lượng đặt | K6: bao | P6: Lập | R6: Duyệt | S6: Thủ kho | T6: Duyệt
A7: Mã sản phẩm | I7: Chiều dài bao sx | K7: mét
A8: Số YCSX | I8: Chiều ngang + hông | K8: mét
A9: Số phiếu SX | I9: Số lượng in thực tế | K9: mét | P9: Nguyễn Minh Quân | R9: Nguyễn Minh Quân
I10: Số màu in | K10: màu
I11: Khổ mành | K11: mét
I12: Khổ màng | K12: mét
I13: Khổ giấy | K13: mét
I14: Khối lượng túi lồng | K14: kg
A16: Tổ sử dụng | B16: STT | C16: Tên NVL | D16: Mã NVL | E16: Số lô / số lot | F16: Đơn vị | G16: Số lượng yêu cầu | H16: Số lượng thực tế xuất | M16: Ngày xuất | Q16: Trả lại | R16: Số lượng sử dụng | S16: Người xuất | T16: Người nhận
H17: Lần 1 | I17: Lần 2 | J17: Lần 3 | K17: Lần 4 | L17: Tổng | M17: Lần 1 | N17: Lần 2 | O17: Lần 3 | P17: Lần 4
S18: Lần 1: Lần 2: Lần 3: Lần 4: | T18: Lần 1: Lần 2: Lần 3: Lần 4: | V18: Mực in OPP LW62 White (Trắng) Ariang | W18: MOCLW62T00001
V19: Mực in OPP 79 Green (Xanh lá) Ariang | W19: MOC79XL000001
V20: Mực in OPP LY11-23 Yellow (Vàng chanh) Arirang | W20: MODALY11V0002
V21: Mực in OPP 94 Black (Đen) Ariang | W21: MOC94D0000001
V22: Mực in OPP Medium Arirang | W22: MOCLME2100001
V23: Mực in OPP 39 Blue Arirang | W23: MODLB39XD0001
B24: 6 | V24: Mực in OPP 16 Red (Đỏ đậm) Arirang | W24: MOD16DS000002
B25: 7 | V25: Mực in OPP 11 Red (Đỏ cờ) Arirang | W25: MOD11DC000001
B26: 8 | V26: Mực in OPP 7549 (Vàng) Arirang (Bestmix) | W26: MOC7549V00001
B27: 9 | V27: Mực in OPP 83-2 (Tím) Violet Arirang | W27: MOC832V000001
B28: 10 | V28: Mực in OPP Cam 52 Arirang | W28: MOC52C000001
A29: Thành phẩm dự kiến: | F29: Cái | V29: Mực in OPP Vàng 2454 (Bestmix) | W29: MOS2454Y00001
A30: GHI CHÚ: | V30: Mực in OPP Tím 2111C (Bestmix) | W30: MOC2111CT0001
A38: Thông tin | B38: ĐVT | C38: Thông số
A39: Số lượng đặt | B39: bao
A40: Chiều dài bao sx | B40: mét | H40: `
A41: Chiều ngang + hông | B41: mét
A42: Số lượng in thực tế | B42: mét
A43: Số màu in | B43: màu
A44: Khổ mành | B44: mét
A45: Khổ màng | B45: mét
A46: Khổ giấy | B46: mét
A47: Khối lượng túi lồng | B47: kg

Sheet Tráng
A1: PHIẾU YẾU CẦU XUẤT KHO NGUYÊN VẬT LIỆU | R1: Mã số: PXK NVL
R2: Ngày ban hành: 8/1/2022
R3: Số phiếu:
A5: Tên khách hàng | C5: =In!C5:G5 -> NHÀ MÁY SX TINH BỘT SẮN TÂN CHÂU-CN CÔNG TY CPNS THỰC PHẨM QUẢNG NGÃI | I5: Thông tin | K5: ĐVT | M5: Thông số | P5: Bộ phận yêu cầu | S5: Bộ phận kho | V5: CÔNG TY TNHH NEO NAM VIỆT | W5: BT1KH00051KP0003 | X5: Bao giấy 25kg AM-20 | Y5: 24BA2DKH00051000014
A6: Tên sản phẩm | C6: =In!C6:G6 -> Bao giấy 25kg AM-20 Tân Châu | I6: Số lượng đặt | K6: bao | M6: =In!M6:N6 -> 5000 | P6: Lập | R6: Duyệt | S6: Thủ kho | T6: Duyệt
A7: Mã sản phẩm | C7: =In!C7:G7 -> BT1KH00563KP0004 | I7: Chiều dài bao | K7: mét | M7: =In!M7:N7 -> 0.92
A8: Số YCSX | C8: =In!C8:G8 -> 26BA2HKH00563000029 | I8: Chiều ngang + hông | K8: mét | M8: =In!M8:N8 -> 0.5
A9: Số phiếu SX | C9: =In!C9 -> SX2607045 | I9: =In!I9:J9 -> Số lượng in thực tế | K9: mét | M9: =M6*M7 -> 4600 | P9: Nguyễn Minh Quân | R9: Nguyễn Minh Quân
I10: Khổ mành | K10: mét | M10: =M8*2+0.07 -> 1.07
I11: Khổ màng | K11: mét
I12: Khổ giấy | K12: mét | M12: 1.01
I13: Khối lượng túi lồng | K13: kg | M13: =In!M14:N14 -> 0.041
A15: Tổ sử dụng | B15: STT | C15: Tên NVL | D15: Mã NVL | E15: Số lô / số lot | F15: Đơn vị | G15: Số lượng yêu cầu | H15: Số lượng thực tế xuất | M15: Ngày xuất | Q15: Trả lại | R15: Số lượng sử dụng | S15: Người xuất | T15: Người nhận
H16: Lần 1 | I16: Lần 2 | J16: Lần 3 | K16: Lần 4 | L16: Tổng | M16: Lần 1 | N16: Lần 2 | O16: Lần 3 | P16: Lần 4
A17: Tổ tráng | B17: 1 | C17: Mành trắng K1060 ĐL70 | D17: MW07010600001 | F17: Kg | G17: =M9*M10*0.07 -> 344.54 | S17: Lần 1: Lần 2: Lần 3: Lần 4: | T17: Lần 1: Lần 2: Lần 3: Lần 4:
B18: 2 | C18: F801C | D18: NHPPNSF801C001 | F18: Kg | G18: =M9*M10*0.02*0.9 -> 88.596
B19: 3 | C19: Taical | D19: NHTEFPP010511 | F19: Kg | G19: =M9*M10*0.02*0.1 -> 9.844
B20: 4
B21: 5
B22: 6
A23: GHI CHÚ:
C25: M9600 | D25: NHPPNSM960001
H33: `

Sheet Dán
A1: PHIẾU YẾU CẦU XUẤT KHO NGUYÊN VẬT LIỆU | R1: Mã số: PXK NVL
R2: Ngày ban hành: 8/1/2022
R3: Số phiếu:
A5: Tên khách hàng | C5: =In!C5:G5 -> NHÀ MÁY SX TINH BỘT SẮN TÂN CHÂU-CN CÔNG TY CPNS THỰC PHẨM QUẢNG NGÃI | I5: Thông tin | K5: ĐVT | M5: Thông số | P5: Bộ phận yêu cầu | S5: Bộ phận kho | V5: CÔNG TY TNHH NEO NAM VIỆT | W5: BT1KH00051KP0003 | X5: Bao giấy 25kg AM-20 | Y5: 24BA2DKH00051000014
A6: Tên sản phẩm | C6: =In!C6:G6 -> Bao giấy 25kg AM-20 Tân Châu | I6: Số lượng đặt | K6: bao | M6: =In!M6:N6 -> 5000 | P6: Lập | R6: Duyệt | S6: Thủ kho | T6: Duyệt
A7: Mã sản phẩm | C7: =In!C7:G7 -> BT1KH00563KP0004 | I7: Chiều dài bao | K7: mét | M7: =In!M7:N7 -> 0.92
A8: Số YCSX | C8: =In!C8:G8 -> 26BA2HKH00563000029 | I8: Chiều ngang + hông | K8: mét | M8: =In!M8:N8 -> 0.5
A9: Số phiếu SX | C9: =In!C9 -> SX2607045 | I9: =In!I9:J9 -> Số lượng in thực tế | K9: mét | M9: =Tráng!M9 -> 4600 | P9: Nguyễn Minh Quân | R9: Nguyễn Minh Quân
I10: Khổ mành | K10: mét | M10: =M8*2+0.06 -> 1.06
I11: Khổ màng | K11: mét
I12: Khổ giấy | K12: mét
I13: Khối lượng túi lồng | K13: kg | M13: =In!M14:N14 -> 0.041
A15: Tổ sử dụng | B15: STT | C15: Tên NVL | D15: Mã NVL | E15: Số lô / số lot | F15: Đơn vị | G15: Số lượng yêu cầu | H15: Số lượng thực tế xuất | M15: Ngày xuất | Q15: Trả lại | R15: Số lượng sử dụng | S15: Người xuất | T15: Người nhận
H16: Lần 1 | I16: Lần 2 | J16: Lần 3 | K16: Lần 4 | L16: Tổng | M16: Lần 1 | N16: Lần 2 | O16: Lần 3 | P16: Lần 4
A17: Dán | B17: 1 | C17: 9415 | D17: NHPPFC9415G01 | F17: Kg | G17: =M9*0.6*3.314/1000 -> 9.14664 | S17: Lần 1: Lần 2: Lần 3: | T17: Lần 1: Lần 2: Lần 3:
B18: 2 | C18: Vistamaxx | D18: NHVITAMAX0001 | F18: Kg | G18: =M9*0.4*3.314/1000 -> 6.09776
B19: 3 | C19: Keo Acrylic | D19: PKACRYLIC0001 | F19: Kg | G19: 0
A20: GHI CHÚ:
H30: `

Sheet Thổi
A1: PHIẾU YẾU CẦU XUẤT KHO NGUYÊN VẬT LIỆU | R1: Mã số: PXK NVL
R2: Ngày ban hành: 8/1/2022
R3: Số phiếu:
A5: Tên khách hàng | C5: =In!C5:G5 -> NHÀ MÁY SX TINH BỘT SẮN TÂN CHÂU-CN CÔNG TY CPNS THỰC PHẨM QUẢNG NGÃI | I5: Thông tin | K5: ĐVT | M5: Thông số | P5: Bộ phận yêu cầu | S5: Bộ phận kho | V5: CÔNG TY TNHH NEO NAM VIỆT | W5: BT1KH00051KP0003 | X5: Bao giấy 25kg AM-20 | Y5: 24BA2DKH00051000014
A6: Tên sản phẩm | C6: =In!C6:G6 -> Bao giấy 25kg AM-20 Tân Châu | I6: Số lượng đặt | K6: bao | M6: =Tráng!M6:N6 -> 5000 | P6: Lập | R6: Duyệt | S6: Thủ kho | T6: Duyệt
A7: Mã sản phẩm | C7: =In!C7:G7 -> BT1KH00563KP0004 | I7: Chiều dài bao | K7: mét | M7: =Tráng!M7:N7 -> 0.92
A8: Số YCSX | C8: =In!C8:G8 -> 26BA2HKH00563000029 | I8: Chiều ngang + hông | K8: mét | M8: =Tráng!M8:N8 -> 0.5
A9: Số phiếu SX | C9: =In!C9 -> SX2607045 | I9: =In!I9:J9 -> Số lượng in thực tế | K9: mét | M9: =Tráng!M9:N9 -> 4600 | P9: Nguyễn Minh Quân | R9: Nguyễn Minh Quân
I10: Khổ mành | K10: mét | M10: =Tráng!M10:N10 -> 1.07
I11: Khổ màng | K11: mét | M11: =Tráng!M11:N11 -> 0
I12: Khổ giấy | K12: mét
I13: Khối lượng túi lồng | K13: kg | M13: =In!M14:N14 -> 0.041
A15: Tổ sử dụng | B15: STT | C15: Tên NVL | D15: Mã NVL | E15: Số lô / số lot | F15: Đơn vị | G15: Số lượng yêu cầu | H15: Số lượng thực tế xuất | M15: Ngày xuất | Q15: Trả lại | R15: Số lượng sử dụng | S15: Người xuất | T15: Người nhận
H16: Lần 1 | I16: Lần 2 | J16: Lần 3 | K16: Lần 4 | L16: Tổng | M16: Lần 1 | N16: Lần 2 | O16: Lần 3 | P16: Lần 4
A17: Tổ thổi | B17: 1 | C17: LDPE | D17: NHLLDPEFD21HN | F17: Kg | G17: =M6*M13 -> 205 | S17: Lần 1: Lần 2: Lần 3: Lần 4: | T17: Lần 1: Lần 2: Lần 3: Lần 4:
B18: 2 | C18: Hạt taical trắng EFPE 75T | D18: NHTEFPE75T01 | F18: Kg | G18: =M6*M13*1.05*0.107*0 -> 0
B19: 3 | C19: Túi PE rin 52x112cm 40gr, đáy dài | D19: TEB0400521121 | F19: Kg | G19: =G17+G18 -> 205
B20: 4 | F20: Cái | G20: =G19/M13 -> 5000
A21: GHI CHÚ:
D23: NHLLDPEFJF10020SP
H31: `

Sheet May
A1: PHIẾU YẾU CẦU XUẤT KHO NGUYÊN VẬT LIỆU | R1: Mã số: PXK NVL
R2: Ngày ban hành: 8/1/2022
R3: Số phiếu:
A5: Tên khách hàng | C5: =In!C5:G5 -> NHÀ MÁY SX TINH BỘT SẮN TÂN CHÂU-CN CÔNG TY CPNS THỰC PHẨM QUẢNG NGÃI | I5: Thông tin | K5: ĐVT | M5: Thông số | P5: Bộ phận yêu cầu | S5: Bộ phận kho | V5: CÔNG TY TNHH NEO NAM VIỆT | W5: BT1KH00051KP0003 | X5: Bao giấy 25kg AM-20 | Y5: 24BA2DKH00051000014
A6: Tên sản phẩm | C6: =In!C6:G6 -> Bao giấy 25kg AM-20 Tân Châu | I6: Số lượng đặt | K6: bao | M6: =In!M6:N6 -> 5000 | P6: Lập | R6: Duyệt | S6: Thủ kho | T6: Duyệt
A7: Mã sản phẩm | C7: =In!C7:G7 -> BT1KH00563KP0004 | I7: Chiều dài bao | K7: mét | M7: =In!M7:N7 -> 0.92
A8: Số YCSX | C8: =In!C8:G8 -> 26BA2HKH00563000029 | I8: Chiều ngang + hông | K8: mét | M8: =In!M8:N8 -> 0.5
A9: Số phiếu SX | C9: =In!C9 -> SX2607045 | I9: =In!I9:J9 -> Số lượng in thực tế | K9: mét | M9: =Tráng!M9:N9 -> 4600 | P9: Nguyễn Minh Quân | R9: Nguyễn Minh Quân
I10: Khổ mành | K10: mét | M10: =M8*2+0.06 -> 1.06
I11: Khổ màng | K11: mét
I12: Khổ giấy | K12: mét
I13: Khối lượng túi lồng | K13: kg | M13: =In!M14:N14 -> 0.041
A15: Tổ sử dụng | B15: STT | C15: Tên NVL | D15: Mã NVL | E15: Số lô / số lot | F15: Đơn vị | G15: Số lượng yêu cầu | H15: Số lượng thực tế xuất | M15: Ngày xuất | Q15: Trả lại | R15: Số lượng sử dụng | S15: Người xuất | T15: Người nhận
H16: Lần 1 | I16: Lần 2 | J16: Lần 3 | K16: Lần 4 | L16: Tổng | M16: Lần 1 | N16: Lần 2 | O16: Lần 3 | P16: Lần 4
A17: May | B17: 1 | C17: Chỉ may trắng | D17: VC10000000001 | F17: Kg | G17: =0.8*M6/1000 -> 4 | S17: Lần 1: Lần 2: Lần 3: | T17: Lần 1: Lần 2: Lần 3:
B18: 2 | C18: Dây bó bao xám | D18: VC40000000001 | F18: Kg | G18: 1
B19: 3 | C19: =Thổi!C19 -> Túi PE rin 52x112cm 40gr, đáy dài | D19: =Thổi!D19 -> TEB0400521121 | F19: Kg
F20: Cái | G20: =Thổi!G20 -> 5000
B21: 4 | C21: Nẹp KP vàng Nhật 6cm | D21: NKPVN06000001 | F21: Kg | G21: =0.06*M6*(0.5+0.12)*0.16 -> 29.76
B22: 5 | C22: Nẹp giấy Kraft nhật vàng 10cm | D22: NKPN0100001 | F22: Kg | G22: =0.1*M6*(0.5+0.12)*0.07 -> 21.7
A23: GHI CHÚ:
H33: `

Sheet Chia biên 1
C1: LỆNH SẢN XUẤT | J1: Số hiệu: QTKSX-BM03
J2: Phiên bản: 00 | N2: =[1]In!J5 -> SX2311007
J3: Hiệu lực: 01/10/2023
A5: Số phiếu YCSX: | C5: =In!C8 -> 26BA2HKH00563000029 | I5: Số phiếu: | J5: =In!C9 -> SX2607045
A6: Mã sản phẩm: | C6: =In!C7 -> BT1KH00563KP0004 | I6: Tổ: | J6: In
A7: Tên sản phẩm: | C7: =In!C6 -> Bao giấy 25kg AM-20 Tân Châu | I7: Ngày bắt đầu: | J7: …..h…..;….../….../2023
A8: Tên khách hàng: | C8: =In!C5 -> NHÀ MÁY SX TINH BỘT SẮN TÂN CHÂU-CN CÔNG TY CPNS THỰC PHẨM QUẢNG NGÃI | I8: Ngày kết thúc: | J8: …..h…..;….../….../2023
C10: Người lập phiếu | H10: Người phê duyệt
A11: Họ và tên | C11: Phạm Thành Luân | H11: Lê Đức Thái Cơ
A12: Chức vụ | C12: Nhân viên kế hoạch | H12: Quản đốc
A13: Chữ ký
A15: Công Đoạn: Chia cuộn | I15: Tổ trưởng kiểm tra
A16: Loại bao | C16: Bao KP, may nẹp đáy bao, LTMS | I16: Kết quả | K16: Xác nhận
A17: Kích thước SX | C17: ='In 1'!O17 -> 500 x 920 | F17: mm
A18: Kích thước TP | C18: ='In 1'!O18 -> 500 x 920 | F18: mm
A19: Số lượng PO | C19: =In!M6 -> 5000 | F19: bao
A20: Sản lượng yêu cầu | C20: =Tráng!M9 -> 4600 | F20: m
A22: Ca vận hành | C22: Ngày | D22: Nhân viên | G22: Chiều dài (mét) | I22: Ghi chú
A23: Ca ngày 7h30 - 19h30
A29: Ca vận hành | C29: Ngày | D29: Nhân viên | G29: Chiều dài (mét) | I29: Ghi chú
A30: Ca đêm 19h30 - 7h30
A35: Tổng sản lượng
A37: Ghi chú | I37: Bên giao (ký, họ & tên) | K37: Bên nhận (ký, họ & tên)

Sheet Ghép 1
C1: LỆNH SẢN XUẤT | J1: Số hiệu: QTKSX-BM03
J2: Phiên bản: 00 | N2: =[1]In!J5 -> SX2311007
J3: Hiệu lực: 01/10/2023
A5: Số phiếu YCSX: | C5: =In!C8 -> 26BA2HKH00563000029 | I5: Số phiếu: | J5: =In!C9 -> SX2607045
A6: Mã sản phẩm: | C6: =In!C7 -> BT1KH00563KP0004 | I6: Tổ: | J6: In
A7: Tên sản phẩm: | C7: =In!C6 -> Bao giấy 25kg AM-20 Tân Châu | I7: Ngày bắt đầu: | J7: …..h…..;….../….../2023
A8: Tên khách hàng: | C8: =In!C5 -> NHÀ MÁY SX TINH BỘT SẮN TÂN CHÂU-CN CÔNG TY CPNS THỰC PHẨM QUẢNG NGÃI | I8: Ngày kết thúc: | J8: …..h…..;….../….../2023
C10: Người lập phiếu | H10: Người phê duyệt
A11: Họ và tên | C11: Phạm Thành Luân
A12: Chức vụ | C12: Nhân viên kế hoạch
A13: Chữ ký
A15: Công Đoạn: Ghép | I15: Tổ trưởng kiểm tra
A16: Loại bao | C16: Bao KP, may nẹp đáy bao, LTMS | I16: Kết quả | K16: Xác nhận
A17: Kích thước SX | C17: ='In 1'!O17 -> 500 x 920 | F17: mm
A18: Kích thước TP | C18: ='In 1'!O18 -> 500 x 920 | F18: mm
A19: Số lượng PO | C19: =In!M6 -> 5000 | F19: bao
A20: Sản lượng yêu cầu | C20: =In!M9 -> 4600 | F20: m
A22: Ca vận hành | C22: Ngày | D22: Nhân viên | G22: Chiều dài (mét) | I22: Ghi chú
A23: Ca ngày 7h30 - 19h30
A29: Ca vận hành | C29: Ngày | D29: Nhân viên | G29: Chiều dài (mét) | I29: Ghi chú
A30: Ca đêm 19h30 - 7h30
A35: Tổng sản lượng
A37: Ghi chú | I37: Bên giao (ký, họ & tên) | K37: Bên nhận (ký, họ & tên)

Sheet Bồi 1
C1: LỆNH SẢN XUẤT | J1: Số hiệu: QTKSX-BM03
J2: Phiên bản: 00 | N2: =[1]In!J5 -> SX2311007
J3: Hiệu lực: 01/10/2023
A5: Số phiếu YCSX: | C5: =In!C8 -> 26BA2HKH00563000029 | I5: Số phiếu: | J5: =In!C9 -> SX2607045
A6: Mã sản phẩm: | C6: =In!C7 -> BT1KH00563KP0004 | I6: Tổ: | J6: In
A7: Tên sản phẩm: | C7: =In!C6 -> Bao giấy 25kg AM-20 Tân Châu | I7: Ngày bắt đầu: | J7: …..h…..;….../….../2023
A8: Tên khách hàng: | C8: =In!C5 -> NHÀ MÁY SX TINH BỘT SẮN TÂN CHÂU-CN CÔNG TY CPNS THỰC PHẨM QUẢNG NGÃI | I8: Ngày kết thúc: | J8: …..h…..;….../….../2023
C10: Người lập phiếu | H10: Người phê duyệt
A11: Họ và tên | C11: Phạm Thành Luân
A12: Chức vụ | C12: Nhân viên kế hoạch
A13: Chữ ký
A15: Công Đoạn: Bồi | I15: Tổ trưởng kiểm tra
A16: Loại bao | C16: Bao KP, may nẹp đáy bao, LTMS | I16: Kết quả | K16: Xác nhận
A17: Kích thước SX | C17: ='In 1'!C17 -> 500 x 920 | F17: mm
A18: Kích thước TP | C18: ='In 1'!C18 -> 500 x 920 | F18: mm
A19: Số lượng PO | C19: =In!M6 -> 5000 | F19: bao
A20: Sản lượng yêu cầu | C20: =In!M9 -> 4600 | F20: m
A22: Ca vận hành | C22: Ngày | D22: Nhân viên | G22: Chiều dài (mét) | I22: Ghi chú
A23: Ca ngày 7h30 - 19h30
A29: Ca vận hành | C29: Ngày | D29: Nhân viên | G29: Chiều dài (mét) | I29: Ghi chú
A30: Ca đêm 19h30 - 7h30
A35: Tổng sản lượng
A37: Ghi chú | I37: Bên giao (ký, họ & tên) | K37: Bên nhận (ký, họ & tên)

Sheet X
U5: CÔNG TY TNHH SẢN XUẤT THƯƠNG MẠI DỊCH VỤ VỮNG TIẾN | V5: XD2KH00309BP0002 | W5: Bao đựng keo dán gạch VISION xám 25kg | X5: 23S03MKH00309000031
A49: KẾ HOẠCH | F49: QUẢN LÝ CHẤT LƯỢNG | M49: NGƯỜI NHẬN
A51: (Ký xác nhận) | F51: (Ký xác nhận) | M51: (Ký xác nhận)
A56: Ngày ........../........./ 2026 | F56: Ngày ........../.........../ 2026 | M56: Ngày ........../.........../ 2026

Sheet Đóng gói 1
C1: LỆNH SẢN XUẤT | J1: Số hiệu: QTKSX-BM03
J2: Phiên bản: 00
J3: Hiệu lực: 2023-11-09 | N3: =[1]In!J5 -> SX2311007
A5: Số phiếu YCSX: | C5: =In!C8 -> 26BA2HKH00563000029 | I5: Số phiếu: | J5: =In!C9 -> SX2607045
A6: Mã sản phẩm: | C6: =In!C7 -> BT1KH00563KP0004 | I6: Tổ: | J6: May
A7: Tên sản phẩm: | C7: =In!C6 -> Bao giấy 25kg AM-20 Tân Châu | I7: Ngày bắt đầu: | J7: …..h…..;….../….../2026
A8: Tên khách hàng: | C8: =In!C5 -> NHÀ MÁY SX TINH BỘT SẮN TÂN CHÂU-CN CÔNG TY CPNS THỰC PHẨM QUẢNG NGÃI | I8: Ngày kết thúc: | J8: …..h…..;….../….../2026
C10: Người lập phiếu | H10: Người phê duyệt
A11: Họ và tên | C11: Nguyễn Minh Quân | H11: Nguyễn Minh Quân
A12: Chức vụ | C12: Nhân viên kế hoạch | H12: TP Kế hoạch
A13: Chữ ký
A15: Công Đoạn: Đóng gói | I15: Tổ trưởng kiểm tra
A16: Loại bao | C16: ='In 1'!C16 -> Bao KP | I16: Kết quả | K16: Xác nhận
A17: Kích thước SX | C17: ='In 1'!C17 -> 500 x 920 | F17: mm
A18: Kích thước TP | C18: ='In 1'!C18 -> 500 x 920 | F18: mm
A19: Số lượng PO | C19: =In!M6 -> 5000 | F19: bao
A20: Sản lượng yêu cầu | C20: =C19 -> 5000 | F20: bao
A22: Ca vận hành | C22: Ngày | D22: Nhân viên | G22: Số lượng (bao) | I22: Ghi chú
A23: Ca ngày 7h30 - 19h30
A29: Ca vận hành | C29: Ngày | D29: Nhân viên | G29: Số lượng (bao) | I29: Ghi chú
A30: Ca đêm 19h30 - 7h30
A35: Tổng sản lượng
A37: Ghi chú | I37: Bên giao (ký, họ & tên) | K37: Bên nhận (ký, họ & tên)

Sheet May 1
C1: LỆNH SẢN XUẤT | J1: Số hiệu: QTKSX-BM03
J2: Phiên bản: 00 | N2: =[1]In!J5 -> SX2311007
J3: Hiệu lực: 2023-11-09
A5: Số phiếu YCSX: | I5: Số phiếu: | J5: =In!C9 -> SX2607045
A6: Mã sản phẩm: | I6: Tổ: | J6: May
A7: Tên sản phẩm: | I7: Ngày bắt đầu: | J7: …..h…..;….../….../2026
A8: Tên khách hàng: | I8: Ngày kết thúc: | J8: …..h…..;….../….../2026
C10: Người lập phiếu | H10: Người phê duyệt
A11: Họ và tên | C11: Nguyễn Minh Quân | H11: Nguyễn Minh Quân
A12: Chức vụ | C12: Nhân viên kế hoạch | H12: TP Kế hoạch
A13: Chữ ký
A15: Công Đoạn: May, lồng túi | I15: Tổ trưởng kiểm tra
A16: Loại bao | I16: Kết quả | K16: Xác nhận
A17: Kích thước SX | F17: mm
A18: Kích thước TP | F18: mm
A19: Số lượng PO | F19: bao
A20: Sản lượng yêu cầu | F20: bao
A22: Ca vận hành | C22: Ngày | D22: Nhân viên | G22: Số lượng (bao) | I22: Ghi chú
A23: Ca ngày 7h30 - 19h30
A29: Ca vận hành | C29: Ngày | D29: Nhân viên | G29: Số lượng (bao) | I29: Ghi chú
A30: Ca đêm 19h30 - 7h30
A35: Tổng sản lượng
A37: Ghi chú | I37: Bên giao (ký, họ & tên) | K37: Bên nhận (ký, họ & tên)

Sheet Thổi 1
C1: LỆNH SẢN XUẤT | J1: Số hiệu: QTKSX-BM03
J2: Phiên bản: 00 | N2: =[1]In!J5 -> SX2311007
J3: Hiệu lực: 2023-11-09
A5: Số phiếu YCSX: | C5: =In!C8 -> 26BA2HKH00563000029 | I5: Số phiếu: | J5: =In!C9 -> SX2607045
A6: Mã sản phẩm: | C6: =In!C7 -> BT1KH00563KP0004 | I6: Tổ: | J6: Thổi
A7: Tên sản phẩm: | C7: =In!C6 -> Bao giấy 25kg AM-20 Tân Châu | I7: Ngày bắt đầu: | J7: …..h…..;….../….../2026
A8: Tên khách hàng: | C8: =In!C5 -> NHÀ MÁY SX TINH BỘT SẮN TÂN CHÂU-CN CÔNG TY CPNS THỰC PHẨM QUẢNG NGÃI | I8: Ngày kết thúc: | J8: …..h…..;….../….../2026
C10: Người lập phiếu | H10: Người phê duyệt
A11: Họ và tên | C11: Nguyễn Minh Quân | H11: Nguyễn Minh Quân
A12: Chức vụ | C12: Nhân viên kế hoạch | H12: TP Kế hoạch
A13: Chữ ký
A15: Công Đoạn: Thổi - Cắt | I15: Tổ trưởng kiểm tra
A16: Loại bao | C16: ='In 1'!C16 -> Bao KP | I16: Kết quả | K16: Xác nhận
A17: Kích thước SX | C17: ='In 1'!C17 -> 500 x 920 | F17: mm
A18: Kích thước TP | C18: ='In 1'!C18 -> 500 x 920 | F18: mm
A19: Số lượng PO | C19: =In!M6 -> 5000 | F19: bao
A20: Sản lượng yêu cầu | C20: =Thổi!G19 -> 205 | F20: kg
A22: Ca vận hành | C22: Ngày | D22: Nhân viên | G22: Khối lượng (Kg) | I22: Ghi chú
A23: Ca ngày 7h30 - 19h30
A29: Ca vận hành | C29: Ngày | D29: Nhân viên | G29: Khối lượng (Kg) | I29: Ghi chú
A30: Ca đêm 19h30 - 7h30
A35: Tổng sản lượng
A37: Ghi chú | I37: Bên giao (ký, họ & tên) | K37: Bên nhận (ký, họ & tên)

Sheet Dán 1
C1: LỆNH SẢN XUẤT | J1: Số hiệu: QTKSX-BM03
J2: Phiên bản: 00 | N2: =[1]In!J5 -> SX2311007
J3: Hiệu lực: 2023-11-09
A5: Số phiếu YCSX: | C5: =In!C8 -> 26BA2HKH00563000029 | I5: Số phiếu: | J5: =In!C9 -> SX2607045
A6: Mã sản phẩm: | C6: =In!C7 -> BT1KH00563KP0004 | I6: Tổ: | J6: Tráng - Dán
A7: Tên sản phẩm: | C7: =In!C6 -> Bao giấy 25kg AM-20 Tân Châu | I7: Ngày bắt đầu: | J7: …..h…..;….../….../2026
A8: Tên khách hàng: | C8: =In!C5 -> NHÀ MÁY SX TINH BỘT SẮN TÂN CHÂU-CN CÔNG TY CPNS THỰC PHẨM QUẢNG NGÃI | I8: Ngày kết thúc: | J8: …..h…..;….../….../2026
C10: Người lập phiếu | H10: Người phê duyệt
A11: Họ và tên | C11: Nguyễn Minh Quân | H11: Nguyễn Minh Quân
A12: Chức vụ | C12: Nhân viên kế hoạch | H12: TP Kế hoạch
A13: Chữ ký
A15: Công Đoạn: Dán Cắt | I15: Tổ trưởng kiểm tra
A16: Loại bao | C16: ='In 1'!C16 -> Bao KP | I16: Kết quả | K16: Xác nhận
A17: Kích thước SX | C17: ='In 1'!C17 -> 500 x 920 | F17: mm
A18: Kích thước TP | C18: ='In 1'!C18 -> 500 x 920 | F18: mm
A19: Số lượng PO | C19: =In!M6 -> 5000 | F19: bao
A20: Sản lượng yêu cầu | C20: =Tráng!M9 -> 4600 | F20: m
A22: Ca vận hành | C22: Ngày | D22: Nhân viên | G22: Chiều dài (mét) | I22: Ghi chú
A23: Ca ngày 7h30 - 19h30
A29: Ca vận hành | C29: Ngày | D29: Nhân viên | G29: Chiều dài (mét) | I29: Ghi chú
A30: Ca đêm 19h30 - 7h30
A35: Tổng sản lượng
A37: Ghi chú | I37: Bên giao (ký, họ & tên) | K37: Bên nhận (ký, họ & tên)

Sheet Tráng 1
C1: LỆNH SẢN XUẤT | J1: Số hiệu: QTKSX-BM03
J2: Phiên bản: 00 | N2: =[1]In!J5 -> SX2311007
J3: Hiệu lực: 2023-11-09
A5: Số phiếu YCSX: | C5: =In!C8 -> 26BA2HKH00563000029 | I5: Số phiếu: | J5: =In!C9 -> SX2607045
A6: Mã sản phẩm: | C6: =In!C7 -> BT1KH00563KP0004 | I6: Tổ: | J6: Tráng - Dán
A7: Tên sản phẩm: | C7: =In!C6 -> Bao giấy 25kg AM-20 Tân Châu | I7: Ngày bắt đầu: | J7: …..h…..;….../….../2026
A8: Tên khách hàng: | C8: =In!C5 -> NHÀ MÁY SX TINH BỘT SẮN TÂN CHÂU-CN CÔNG TY CPNS THỰC PHẨM QUẢNG NGÃI | I8: Ngày kết thúc: | J8: …..h…..;….../….../2026
C10: Người lập phiếu | H10: Người phê duyệt
A11: Họ và tên | C11: Nguyễn Minh Quân | H11: Nguyễn Minh Quân
A12: Chức vụ | C12: Nhân viên kế hoạch | H12: TP Kế hoạch
A13: Chữ ký
A15: Công Đoạn: Tráng Ghép | I15: Tổ trưởng kiểm tra
A16: Loại bao | C16: ='In 1'!C16 -> Bao KP | I16: Kết quả | K16: Xác nhận
A17: Kích thước SX | C17: ='In 1'!C17 -> 500 x 920 | F17: mm
A18: Kích thước TP | C18: ='In 1'!C18 -> 500 x 920 | F18: mm
A19: Số lượng PO | C19: =In!M6 -> 5000 | F19: bao
A20: Sản lượng yêu cầu | C20: =Tráng!M9 -> 4600 | F20: m
A22: Ca vận hành | C22: Ngày | D22: Nhân viên | G22: Chiều dài (mét) | I22: Ghi chú
A23: Ca ngày 7h30 - 19h30
A29: Ca vận hành | C29: Ngày | D29: Nhân viên | G29: Chiều dài (mét) | I29: Ghi chú
A30: Ca đêm 19h30 - 7h30
A35: Tổng sản lượng
A37: Ghi chú | I37: Bên giao (ký, họ & tên) | K37: Bên nhận (ký, họ & tên)

Sheet In 1
C1: LỆNH SẢN XUẤT | J1: Số hiệu: QTKSX-BM03
J2: Phiên bản: 00
J3: Hiệu lực: 2023-11-09
A5: Số phiếu YCSX: | C5: =In!C8 -> 26BA2HKH00563000029 | I5: Số phiếu: | J5: =In!C9 -> SX2607045
A6: Mã sản phẩm: | C6: =In!C7 -> BT1KH00563KP0004 | I6: Tổ: | J6: In
A7: Tên sản phẩm: | C7: =In!C6 -> Bao giấy 25kg AM-20 Tân Châu | I7: Ngày bắt đầu: | J7: …..h…..;….../….../2026
A8: Tên khách hàng: | C8: =In!C5 -> NHÀ MÁY SX TINH BỘT SẮN TÂN CHÂU-CN CÔNG TY CPNS THỰC PHẨM QUẢNG NGÃI | I8: Ngày kết thúc: | J8: …..h…..;….../….../2026
C10: Người lập phiếu | H10: Người phê duyệt
A11: Họ và tên | C11: Nguyễn Minh Quân | H11: Nguyễn Minh Quân
A12: Chức vụ | C12: Nhân viên kế hoạch | H12: TP Kế hoạch
A13: Chữ ký
A15: Công Đoạn: In Flexo | I15: Tổ trưởng kiểm tra
A16: Loại bao | C16: =O16 -> Bao KP | I16: Kết quả | K16: Xác nhận | N16: Loại bao | O16: Bao KP
A17: Kích thước SX | C17: =O17 -> 500 x 920 | F17: mm | N17: Kích thước SX | O17: 500 x 920
A18: Kích thước TP | C18: =O18 -> 500 x 920 | F18: mm | N18: Kích thước TP | O18: 500 x 920
A19: Số lượng PO | C19: =In!M6 -> 5000 | F19: bao | N19: Số lượng PO | O19: 20000
A20: Sản lượng yêu cầu | C20: =In!M9 -> 4600 | F20: m
A22: Ca vận hành | C22: Ngày | D22: Nhân viên | G22: Chiều dài (mét) | I22: Ghi chú
A23: Ca ngày 7h30 - 19h30
A29: Ca vận hành | C29: Ngày | D29: Nhân viên | G29: Chiều dài (mét) | I29: Ghi chú
A30: Ca đêm 19h30 - 7h30
A35: Tổng sản lượng
A37: Ghi chú | I37: Bên giao (ký, họ & tên) | K37: Bên nhận (ký, họ & tên)

Sheet XX

Sheet In 2
C1: NHẬT KÝ SẢN XUẤT | K1: Số hiệu: QTSXU-BM01
K2: Phiên bản: 00
K3: Hiệu lực: 2023-11-09
A5: Số phiếu YCSX: | C5: =In!C8 -> 26BA2HKH00563000029 | I5: Số phiếu: | K5: =In!C9 -> SX2607045 | U5: CÔNG TY TNHH RANGSEY-KHANHA | V5: NN2KH00240BP0001 | W5: Bao Lúa giống Rangsey 40kg (đỏ) | X5: 23S03LKH00240000056
A6: Mã sản phẩm: | C6: =In!C7 -> BT1KH00563KP0004 | I6: Tổ : | K6: In
A7: Tên sản phẩm: | C7: =In!C6 -> Bao giấy 25kg AM-20 Tân Châu | I7: Ngày bắt đầu: | K7: …..h…..;….../….../2026
A8: Tên khách hàng: | C8: =In!C5 -> NHÀ MÁY SX TINH BỘT SẮN TÂN CHÂU-CN CÔNG TY CPNS THỰC PHẨM QUẢNG NGÃI | I8: Ngày kết thúc: | K8: …..h…..;….../….../2026
C10: Người lập phiếu | H10: Người phê duyệt
A11: Họ và tên | C11: Nguyễn Minh Quân | H11: Nguyễn Minh Quân
A12: Chức vụ | C12: Nhân viên kế hoạch | H12: TP Kế hoạch
A13: Chữ ký
A15: Công Đoạn: In Flexo | J15: Nhân viên kiểm tra NVL
A16: Số lượng theo PO (Mét) | C16: =In!M9 -> 4600 | E16: Số lượng thực tế (Mét) | G16: =In!M9 -> 4600 | J16: Kết quả | L16: Xác nhận | O16: =9936-5000 -> 4936
A17: STT | B17: Tên NVL | C17: Mã NVL | D17: Tỷ lệ | E17: ĐVT | F17: Định mức | G17: Thực tế | H17: Trả về
B18: =In!C18 -> Giấy Kraft vàng Nhật K1020 ĐL70 | C18: =In!D18 -> GN07010200001 | E18: Kg | F18: =In!G18 -> 328.44
E19: Mét | F19: =In!G19 -> 4600
A21: 1 | B21: Đen 92 | C21: MFB92D0000001 | E21: Kg | F21: 8
J22: Kiểm soát chất lượng
J23: Kết quả | L23: Xác nhận
A25: 2 | B25: Đỏ 1379R | C25: MFB1379R0000001 | E25: Kg | F25: 8
J27: Giám sát kỹ thuật
J28: Kết quả | L28: Xác nhận
A31: 3 | B31: Nâu 7204N | C31: MFBN7204NBXT001 | E31: Kg | F31: 8
J32: STT | K32: Nhân viên | L32: Chức Vụ | M32: Ký tên
J33: 1
J34: 2
J35: 3
J36: 4
J37: 5
J38: 6
A40: STT | B40: Thông số quá trình | D40: Tiêu chuẩn | E40: Kết quả kiểm tra | G40: Đơn vị | H40: Xác nhận | J40: Phế liệu | K40: Khối lượng (Kg) | L40: Người cân | M40: QLCL
E41: ____:____ | F41: ____:____
A42: 1 | B42: Kích thước nhông in | D42: 920 ± 10 | G42: mm
A43: 2 | B43: Tốc độ in | D43: 140 ± 10 | G43: Hz
A44: 3 | B44: Tốc độ quấn cuộn | D44: Từ 0 - 5000 mét: 750 ± 50 Lớn hơn 5000 mét: 950 ± 50 | G44: R.P.M
A53: STT | B53: Thông số sản phẩm | D53: Tiêu chuẩn | E53: Kết quả kiểm tra | G53: Đơn vị | H53: Xác nhận | J53: Ghi chú
E54: ____:____ | F54: ____:____
A55: 1 | B55: Kích thước | D55: Đúng yêu cầu
A56: 2 | B56: Màu sắc trên giấy | D56: ΔE ≤ 1.6
A57: 3 | B57: Độ bám dính | D57: Không bong tróc mực
...

Sheet Chia biên 2
C1: NHẬT KÝ SẢN XUẤT | K1: Số hiệu: QTSXU-BM01
K2: Phiên bản: 00
K3: Hiệu lực: 01/10/2023
A5: Số phiếu YCSX: | I5: Số phiếu: | K5: ='In 2'!K5 -> SX2607045 | U5: CÔNG TY TNHH RANGSEY-KHANHA | V5: NN2KH00240BP0001 | W5: Bao Lúa giống Rangsey 40kg (đỏ) | X5: 23S03LKH00240000056
A6: Mã sản phẩm: | I6: Tổ : | K6: In
A7: Tên sản phẩm: | I7: Ngày bắt đầu: | K7: ='[2]Dệt mành'!J8 -> …..h…..;….../….../2023
A8: Tên khách hàng: | I8: Ngày kết thúc: | K8: ='[2]Dệt mành'!J9 -> …..h…..;….../….../2023
C10: Người lập phiếu | H10: Người phê duyệt
A11: Họ và tên | C11: Phạm Thành Luân | H11: Lê Đức Thái Cơ
A12: Chức vụ | C12: Nhân viên kế hoạch | H12: Quản đốc
A13: Chữ ký
A15: Công Đoạn: Chia Cuộn | J15: Nhân viên kiểm tra NVL
A16: Số lượng theo PO (Mét) | E16: Số lượng thực tế (Mét) | J16: Kết quả | L16: Xác nhận
A17: STT | B17: Tên NVL | D17: Mã NVL | E17: Tỷ lệ | F17: ĐVT | G17: Định mức | H17: Thực tế
A18: 1
A19: 2
A20: 3 | J20: Kiểm soát chất lượng
A21: 4 | J21: Kết quả | L21: Xác nhận
A22: 5
A23: 6
A25: STT | B25: Thông số quá trình | D25: Tiêu chuẩn | E25: Kết quả kiểm tra | G25: Đơn vị | H25: Xác nhận | J25: STT | K25: Nhân viên | L25: Chức Vụ | M25: Ký tên
E26: ____:____ | F26: ____:____ | J26: 1
A27: 1 | B27: Lực thắng cuộn | D27: 3.5 ± 0.5 | G27: V | J27: 2
A28: 2 | B28: Lực quấn | D28: 37.5 ± 2.5 | G28: RPM | J28: 3
A29: 3 | B29: Tốc độ kéo | D29: 110 ± 10 | G29: Hz | J29: 4
A30: 4 | B30: Khoảng cách từ điểm cắt đến biên cắt | D30: 2 ± 1 | G30: mm | J30: 5
A31: 5
A32: 6 | J32: Phế liệu | K32: Khối lượng (Kg) | L32: Người cân | M32: QLCL
A33: 7
A34: 8
A35: 9
A36: 10
A37: 11
A39: STT | B39: Thông số sản phẩm | D39: Tiêu chuẩn | E39: Kết quả kiểm tra | G39: Đơn vị | H39: Xác nhận
E40: ____:____ | F40: ____:____
A41: 1 | B41: Cuộn xả tối đa | D41: 8000 | G41: m
A42: 2 | B42: Cuộn quấn tối đa | D42: 8000 | G42: m
A43: 3 | B43: Khổ màng chia biên | D43: =O43 -> -20 | G43: mm | O43: =(In!M12-0.02)*1000 -> -20
A44: 4 | B44: Ngoại quan | D44: Không gấp màng Không đổ cuộn Không trầy xước
J45: Ghi chú
...

Sheet Tráng 2
C1: NHẬT KÝ SẢN XUẤT | N1: Số hiệu: QTSXU-BM01
N2: Phiên bản: 00
N3: Hiệu lực: 2023-11-09
A5: Số phiếu YCSX: | C5: ='In 2'!C5 -> 26BA2HKH00563000029 | M5: Số phiếu: | N5: ='In 2'!K5 -> SX2607045
A6: Mã sản phẩm: | C6: ='In 2'!C6 -> BT1KH00563KP0004 | M6: Tổ : | N6: Tráng - Dán
A7: Tên sản phẩm: | C7: ='In 2'!C7 -> Bao giấy 25kg AM-20 Tân Châu | M7: Ngày bắt đầu: | N7: …..h…..;….../….../2026
A8: Tên khách hàng: | C8: ='In 2'!C8 -> NHÀ MÁY SX TINH BỘT SẮN TÂN CHÂU-CN CÔNG TY CPNS THỰC PHẨM QUẢNG NGÃI | M8: Ngày kết thúc: | N8: …..h…..;….../….../2026
C10: Người lập phiếu | K10: Người phê duyệt
A11: Họ và tên | C11: Nguyễn Minh Quân | K11: Nguyễn Minh Quân
A12: Chức vụ | C12: Nhân viên kế hoạch | K12: TP Kế hoạch
A13: Chữ ký
A15: Công Đoạn: Tráng Ghép | J15: Nhân viên kiểm tra NVL
A16: Thành phẩm chia biên | C16: =Tráng!M9 -> 4600 | F16: Mét | J16: Kết quả | N16: Xác nhận
A17: Mã mành sản xuất
A19: Khối lượng nhựa cần | C19: =G22+G23 -> 98.44 | F19: Kg
A20: STT | B20: Tên NVL | C20: Mã NVL | E20: Tỷ lệ | F20: ĐVT | G20: Định mức | H20: Thực tế
A21: 2 | B21: =Tráng!C17 -> Mành trắng K1060 ĐL70 | C21: =Tráng!D17 -> MW07010600001 | F21: Kg | G21: =Tráng!G17 -> 344.54 | J21: Kiểm soát chất lượng
A22: 3 | B22: =Tráng!C18 -> F801C | C22: =Tráng!D18 -> NHPPNSF801C001 | E22: 0.9 | F22: Kg | G22: =Tráng!G18 -> 88.596 | J22: Kết quả | N22: Xác nhận
A23: 4 | B23: =Tráng!C19 -> Taical | C23: =Tráng!D19 -> NHTEFPP010511 | E23: 0.1 | F23: Kg | G23: =Tráng!G19 -> 9.844
J25: Giám sát kỹ thuật
J26: Kết quả | N26: Xác nhận
A29: STT | B29: Thông số quá trình | D29: Tiêu chuẩn | E29: Kết quả kiểm tra | G29: Đơn vị | H29: Xác nhận | J29: STT | K29: Thông số sản phẩm | M29: Tiêu chuẩn | N29: Kết quả kiểm tra | P29: Đơn vị | Q29: Xác nhận
E30: ____:____ | F30: ____:____ | N30: ____:____ | O30: ____:____
A31: 1 | B31: Tốc độ máy | D31: 97 ± 5 | G31: m/phút | J31: 1 | K31: Độ rộng đường dán | M31: 35 - 40 | P31: mm
A32: 2 | B32: Lực thắng cuộn | D32: 5 - 24 | G32: V | J32: 2 | K32: Khổ thành phẩm | M32: 1040 | P32: mm
A33: 3 | B33: Lực ép lô | D33: 5.5 ± 0.5 | G33: Bar | J33: 3 | K33: Định lượng TP | M33: 160 ± 3 | P33: G/m²
A34: 4 | B34: Nhiệt độ làm mát lô | D34: 24 ± 2 | G34: °C | J34: 4 | K34: Định lượng keo | M34: 20 | P34: G/m²
A35: 5 | B35: Tốc độ quấn cuộn | D35: 65 ± 5 | G35: Hz | J35: 5 | K35: Độ bám dính | M35: Không bong tróc
A36: 6 | B36: Thông số nhiệt đầu khuôn vùng 1 | D36: 290 ± 2 | G36: °C | J36: 6 | K36: Ngoại quan | M36: Không nhăn Không gồ Không cao mép Không đổ cuộn
A37: 7 | B37: Thông số nhiệt đầu khuôn vùng 2 | D37: 290 ± 2 | G37: °C
A38: 8 | B38: Thông số nhiệt đầu khuôn vùng 3 | D38: 290 ± 2 | G38: °C
A39: 9 | B39: Thông số nhiệt đầu khuôn vùng 4 | D39: 290 ± 2 | G39: °C
A40: 10 | B40: Thông số nhiệt đầu khuôn vùng 5 | D40: 290 ± 2 | G40: °C | J40: STT | K40: Nhân viên | N40: Chức vụ | P40: Ký tên
A41: 11 | B41: Thông số nhiệt đầu khuôn vùng 6 | D41: 290 ± 2 | G41: °C | J41: 1
A42: 12 | B42: Thông số nhiệt đầu khuôn vùng 7 | D42: 290 ± 2 | G42: °C | J42: 2
A43: 13 | B43: Thông số nhiệt trục vít vùng 0 | D43: 220 ± 2 | G43: °C | J43: 3
A44: 14 | B44: Thông số nhiệt trục vít vùng 1 | D44: 225 ± 2 | G44: °C | J44: 4
A45: 15 | B45: Thông số nhiệt trục vít vùng 2 | D45: 250 ± 2 | G45: °C | J45: 5
A46: 16 | B46: Thông số nhiệt trục vít vùng 3 | D46: 255 ± 2 | G46: °C | J46: 6
A47: 17 | B47: Thông số nhiệt trục vít vùng 4 | D47: 260 ± 2 | G47: °C
...

Sheet Dán 2
C1: NHẬT KÝ SẢN XUẤT | K1: Số hiệu: QTSXU-BM01
K2: Phiên bản: 00
K3: Hiệu lực: 2023-11-09
A5: Số phiếu YCSX: | I5: Số phiếu: | K5: ='In 2'!K5 -> SX2607045 | U5: CÔNG TY TNHH RANGSEY-KHANHA | V5: NN2KH00240BP0001 | W5: Bao Lúa giống Rangsey 40kg (đỏ) | X5: 23S03LKH00240000056
A6: Mã sản phẩm: | I6: Tổ : | K6: Tráng - Dán
A7: Tên sản phẩm: | I7: Ngày bắt đầu: | K7: …..h…..;….../….../2026
A8: Tên khách hàng: | I8: Ngày kết thúc: | K8: …..h…..;….../….../2026
C10: Người lập phiếu | H10: Người phê duyệt
A11: Họ và tên | C11: Nguyễn Minh Quân | H11: Nguyễn Minh Quân
A12: Chức vụ | C12: Nhân viên kế hoạch | H12: TP Kế hoạch
A13: Chữ ký
A15: Công Đoạn: Dán Cắt | J15: Nhân viên kiểm tra NVL
A16: Khối lượng nhựa cần | F16: Kg | J16: Kết quả | L16: Xác nhận
A17: STT | B17: Tên NVL | D17: Mã NVL | E17: Tỷ lệ | F17: ĐVT | G17: Định mức | H17: Thực tế
A18: 1
A19: 2
A20: 3 | J20: Kiểm soát chất lượng
A21: 4 | J21: Kết quả | L21: Xác nhận
A22: 5
A23: 6
J24: Giám sát kỹ thuật
J25: Kết quả | L25: Xác nhận
A28: STT | B28: Thông số quá trình | D28: Tiêu chuẩn | E28: Kết quả kiểm tra | G28: Đơn vị | H28: Xác nhận | J28: STT | K28: Nhân viên | L28: Chức Vụ | M28: Ký tên
E29: ____:____ | F29: ____:____ | J29: 1
A30: 1 | B30: Tốc độ máy | D30: 100 ± 10 | G30: m/phút | J30: 2
A31: 2 | B31: Tốc độ keo | D31: 35 ± 5 | G31: Hz | J31: 3
A32: 3 | B32: Lái cuộn | D32: 570 ± 10 | G32: mm | J32: 4
A33: 4 | B33: Lực ép đường dán | D33: 2 ± 1 | G33: Bar | J33: 5
A34: 5 | B34: Kích thước nhông | D34: 920 | G34: mm
A35: 6 | B35: Số đường keo | D35: 7 | G35: Đường | J35: Phế liệu | K35: Khối lượng (Kg) | L35: Người cân | M35: QLCL
A36: 7 | B36: Điều chỉnh dưỡng | D36: 200 ± 10 | G36: mm
A37: 8 | B37: Độ sâu tối đa của dĩa xếp hong | D37: 50 ± 3 | G37: mm
A38: 9 | B38: Nhiệt độ đầu khuôn | D38: 270 ± 5 | G38: °C
A39: 10 | B39: Nhiệt độ trục vít vùng 1 | D39: 255 ± 5 | G39: °C
A40: 11 | B40: Nhiệt độ trục vít vùng 2 | D40: 280 ± 5 | G40: °C
A41: 12 | B41: Nhiệt độ trục vít vùng 3 | D41: 280 ± 5 | G41: °C
A43: STT | B43: Thông số sản phẩm | D43: Tiêu chuẩn | E43: Kết quả kiểm tra | G43: Đơn vị | H43: Xác nhận
E44: ____:____ | F44: ____:____
A45: 1 | B45: Kích thước chiều dài | D45: 920 ± 10 | G45: mm
A46: 2 | B46: Kích thước chiều rộng | D46: 500 ± 10 | G46: mm
...

Sheet Thổi 2
C1: NHẬT KÝ SẢN XUẤT | K1: Số hiệu: QTSXU-BM01
K2: Phiên bản: 00
K3: Hiệu lực: 2023-11-09
A5: Số phiếu YCSX: | C5: ='In 2'!C5 -> 26BA2HKH00563000029 | I5: Số phiếu: | K5: ='In 2'!K5 -> SX2607045
A6: Mã sản phẩm: | C6: ='In 2'!C6 -> BT1KH00563KP0004 | I6: Tổ : | K6: Thổi
A7: Tên sản phẩm: | C7: ='In 2'!C7 -> Bao giấy 25kg AM-20 Tân Châu | I7: Ngày bắt đầu: | K7: …..h…..;….../….../2026
A8: Tên khách hàng: | C8: ='In 2'!C8 -> NHÀ MÁY SX TINH BỘT SẮN TÂN CHÂU-CN CÔNG TY CPNS THỰC PHẨM QUẢNG NGÃI | I8: Ngày kết thúc: | K8: …..h…..;….../….../2026
C10: Người lập phiếu | H10: Người phê duyệt
A11: Họ và tên | C11: Nguyễn Minh Quân | H11: Nguyễn Minh Quân
A12: Chức vụ | C12: Nhân viên kế hoạch | H12: TP Kế hoạch
A13: Chữ ký
A15: Công Đoạn: Thổi - Cắt | J15: Nhân viên kiểm tra NVL
A16: Khối lượng nhựa cần | D16: =G18+G19 -> 205 | F16: Kg | J16: Kết quả | L16: Xác nhận
A17: STT | B17: Tên NVL | D17: Mã NVL | E17: Tỷ lệ | F17: ĐVT | G17: Định mức | H17: Thực tế
A18: 1 | B18: =Thổi!C17 -> LDPE | D18: =Thổi!D17 -> NHLLDPEFD21HN | E18: 1 | F18: Kg | G18: =Thổi!G17 -> 205
A19: 2 | B19: =Thổi!C18 -> Hạt taical trắng EFPE 75T | D19: =Thổi!D18 -> NHTEFPE75T01 | E19: 0 | F19: Kg | G19: =Thổi!G18 -> 0
A20: 3 | B20: =Thổi!C19 -> Túi PE rin 52x112cm 40gr, đáy dài | D20: =Thổi!D19 -> TEB0400521121 | F20: Kg | G20: =Thổi!G19 -> 205 | J20: Kiểm soát chất lượng
A21: 4 | F21: Cái | G21: =Thổi!G20 -> 5000 | J21: Kết quả | L21: Xác nhận
A22: 5
A23: 6
J24: Giám sát kỹ thuật
J25: Kết quả | L25: Xác nhận
A28: STT | B28: Thông số quá trình | D28: Tiêu chuẩn | E28: Kết quả kiểm tra | G28: Đơn vị | H28: Xác nhận | J28: STT | K28: Nhân viên | L28: Chức Vụ | M28: Ký tên
E29: ____:____ | F29: ____:____ | J29: 1
A30: 1 | B30: Lực quấn cuộn | D30: 100 ± 10 | G30: RPM | J30: 2
A31: 2 | B31: Thông số nhiệt vùng 1 | D31: 35 ± 5 | G31: °C | J31: 3
A32: 3 | B32: Thông số nhiệt vùng 2 | D32: 570 ± 10 | G32: °C | J32: 4
A33: 4 | B33: Thông số nhiệt vùng 3 | D33: 150 | G33: °C | J33: 5
A34: 5 | B34: Thông số nhiệt vùng 4 | D34: 170 | G34: °C
A35: 6 | B35: Thông số nhiệt vùng 5 | D35: 170 | G35: °C | J35: Phế liệu | K35: Khối lượng (Kg) | L35: Người cân | M35: QLCL
A36: 7 | B36: Tốc độ đùn keo | D36: 55 ± 5 | G36: Hz
A37: 8 | B37: Tốc độ kéo bóng | D37: 35 ± 5 | G37: Hz
A38: 9 | O38: =52*112*2*0.91 -> 10599.68
A39: 10 | O39: =40*10000/O38 -> 37.736988
A41: STT | B41: Thông số quá trình | D41: Tiêu chuẩn | E41: Kết quả kiểm tra | G41: Đơn vị | H41: Xác nhận
E42: ____:____ | F42: ____:____
A43: 1 | B43: Kích thước chiều rộng | D43: 520 ± 10 | G43: mm
A44: 2 | B44: Kích thước chiều dài | D44: 1120 ± 10 | G44: mm
A45: 3 | B45: Kích thước đáy | D45: 40 - 50 | G45: mm
A46: 4 | B46: Độ dày | D46: 38 ± 1 | G46: μm
...

Sheet May 2
C1: NHẬT KÝ SẢN XUẤT | K1: Số hiệu: QTSXU-BM01
K2: Phiên bản: 00
K3: Hiệu lực: 2023-11-09
A5: Số phiếu YCSX: | C5: ='In 2'!C5 -> 26BA2HKH00563000029 | I5: Số phiếu: | K5: ='In 2'!K5 -> SX2607045 | U5: CÔNG TY TNHH RANGSEY-KHANHA | V5: NN2KH00240BP0001 | W5: Bao Lúa giống Rangsey 40kg (đỏ) | X5: 23S03LKH00240000056
A6: Mã sản phẩm: | C6: ='In 2'!C6 -> BT1KH00563KP0004 | I6: Tổ : | K6: May
A7: Tên sản phẩm: | C7: ='In 2'!C7 -> Bao giấy 25kg AM-20 Tân Châu | I7: Ngày bắt đầu: | K7: …..h…..;….../….../2026
A8: Tên khách hàng: | C8: ='In 2'!C8 -> NHÀ MÁY SX TINH BỘT SẮN TÂN CHÂU-CN CÔNG TY CPNS THỰC PHẨM QUẢNG NGÃI | I8: Ngày kết thúc: | K8: …..h…..;….../….../2026
C10: Người lập phiếu | H10: Người phê duyệt
A11: Họ và tên | C11: Nguyễn Minh Quân | H11: Nguyễn Minh Quân
A12: Chức vụ | C12: Nhân viên kế hoạch | H12: TP Kế hoạch
A13: Chữ ký
A15: Công Đoạn: May - Lồng túi | J15: Nhân viên kiểm tra NVL
A16: Số lượng theo PO | C16: =In!M6 -> 5000 | F16: Bao | J16: Kết quả | L16: Xác nhận
A17: STT | B17: Tên NVL | C17: Mã NVL | E17: ĐVT | F17: Tạm ứng | G17: Định mức | H17: Trả về
A18: 1 | B18: =May!C17 -> Chỉ may trắng | C18: =May!D17 -> VC10000000001 | E18: Kg | F18: =May!G17 -> 4
A19: 2 | B19: =May!C19 -> Túi PE rin 52x112cm 40gr, đáy dài | C19: =May!D19 -> TEB0400521121 | E19: Kg | F19: =May!G19 -> 0
A20: 3 | E20: Cái | F20: =May!G20 -> 5000 | J20: Kiểm soát chất lượng
A21: 4 | B21: =May!C21 -> Nẹp KP vàng Nhật 6cm | C21: =May!D21 -> NKPVN06000001 | E21: Kg | F21: =May!G21 -> 29.76 | J21: Kết quả | L21: Xác nhận
A22: 5 | B22: =May!C22 -> Nẹp giấy Kraft nhật vàng 10cm | C22: =May!D22 -> NKPN0100001 | E22: Kg | F22: =May!G22 -> 21.7
A23: 6
J24: Giám sát kỹ thuật
J25: Kết quả | L25: Xác nhận
A28: STT | B28: Thông số | C28: Tiêu chuẩn | E28: Kết quả kiểm tra | G28: Đơn vị | H28: Xác nhận | J28: STT | K28: Nhân viên | L28: Chức Vụ | M28: Ký tên
E29: ____:____ | F29: ____:____ | J29: 1
A30: 1 | B30: May | C30: Không bỏ mũi Không đứt chỉ, rối chỉ Không dính dầu nhớt | J30: 2
J31: 3
J32: 4
A33: 2 | B33: Cắt nẹp | C33: Chênh lệch 2 đầu bao ≤20mm | J33: 5
A35: 3 | B35: Quy cách | C35: LTMS | J35: Phế liệu | K35: Khối lượng (Kg) | L35: Người cân | M35: QLCL
J48: Ghi chú
A56: Thành phẩm may | J56: Bên giao (ký, họ & tên) | L56: Bên nhận (ký, họ & tên)
A57: Khối lượng (Kg) | E57: Số lượng (Bao)

Sheet Đóng gói 2
C1: NHẬT KÝ SẢN XUẤT | K1: Số hiệu: QTSXU-BM01
K2: Phiên bản: 00
K3: Hiệu lực: 2023-11-09
A5: Số phiếu YCSX: | C5: ='In 2'!C5 -> 26BA2HKH00563000029 | I5: Số phiếu: | K5: ='In 2'!K5 -> SX2607045 | U5: CÔNG TY TNHH RANGSEY-KHANHA | V5: NN2KH00240BP0001 | W5: Bao Lúa giống Rangsey 40kg (đỏ) | X5: 23S03LKH00240000056
A6: Mã sản phẩm: | C6: ='In 2'!C6 -> BT1KH00563KP0004 | I6: Tổ : | K6: May
A7: Tên sản phẩm: | C7: ='In 2'!C7 -> Bao giấy 25kg AM-20 Tân Châu | I7: Ngày bắt đầu: | K7: …..h…..;….../….../2026
A8: Tên khách hàng: | C8: ='In 2'!C8 -> NHÀ MÁY SX TINH BỘT SẮN TÂN CHÂU-CN CÔNG TY CPNS THỰC PHẨM QUẢNG NGÃI | I8: Ngày kết thúc: | K8: …..h…..;….../….../2026
C10: Người lập phiếu | H10: Người phê duyệt
A11: Họ và tên | C11: Nguyễn Minh Quân | H11: Nguyễn Minh Quân
A12: Chức vụ | C12: Nhân viên kế hoạch | H12: TP Kế hoạch
A13: Chữ ký
A15: Công Đoạn: Đóng Gói | J15: Nhân viên kiểm tra NVL
A16: Số lượng theo PO | C16: =In!M6 -> 5000 | F16: Bao | J16: Kết quả | L16: Xác nhận
A17: STT | B17: Tên NVL | C17: Mã NVL | E17: Tỷ lệ | F17: ĐVT | G17: Định mức | H17: Thực tế
A18: 1 | B18: =May!C18 -> Dây bó bao xám | C18: =May!D18 -> VC40000000001 | F18: Kg | G18: =May!G18 -> 1
A19: 2
A20: 3 | J20: Kiểm soát chất lượng
A21: 4 | J21: Kết quả | L21: Xác nhận
A22: 5
A23: 6
A25: STT | B25: Thông số | C25: Tiêu chuẩn | E25: Kết quả kiểm tra | G25: Đơn vị | H25: Xác nhận | J25: STT | K25: Nhân viên | L25: Chức Vụ | M25: Ký tên
E26: ____:____ | F26: ____:____ | J26: 1
A27: 1 | B27: Bó bao | C27: 100 bao/bó Lật mặt trước bao lên trên | J27: 2
J28: 3
A29: 2 | B29: Đóng gói | C29: Đúng yêu cầu số bao/kiện Buộc dây chắc, không xộc xệch Đúng màu sắc dây theo yêu cầu Không có dị vật rơi vào | J29: 4
J30: 5
A32: 3 | B32: Quy cách | C32: 200 bao/kiện | J32: Phế liệu | K32: Khối lượng (Kg) | L32: Người cân | M32: QLCL
J43: Ghi chú
A50: Thành phẩm | J50: Bên giao (ký, họ & tên) | L50: Bên nhận (ký, họ & tên)
A51: Khối lượng (Kg) | D51: Số lượng (Bó) | F51: Số lượng (Bao)
